Workbook

Sheet Statistics
A1: =CONCATENATE(IF(OR(B2="Not checked",B3="Not checked",B5="Not checked",B7="Not checked",B9="Not checked",B17="Not checked",B18="Not checked",B11="Not checked",B12="Not checked",B13="Not checked",B14="Not checked",B15="Not checked",B16="Not checked"),"Not fully checked","")," ",IFERROR(IF(OR(NOT(K2),NOT(K3),NOT(K5),NOT(K7),NOT(K9),NOT(K17),NOT(K18),NOT(K11),NOT(K12),NOT(K13),NOT(K14),NOT(K15),NOT(K16)),"FAIL","PASS"),"")) | B1: Conclusion | C1: MIN | D1: TYP | E1: MAX | F1: Tolerance | G1: IIS MIN | H1: IIS | I1: IIS MAX | J1: IIS Tol | K1: OC model | L1: CHOT CV500U5-T02 | O1: Tolerance | Q1: 0.065 | R1: =IF(D2>0,IF(AND(D2>=H2*(1-Q1),C2>=G2*(1-Q1)),TRUE,FALSE),"Not checked") -> TRUE | X1: HD 5 @ 1/6
A2: Brightness | B2: =IF(OR(ISBLANK(C2),C2=0, ISBLANK(D2),D2=0), "NOT CHECKED", IF(OR(AND(NOT(AND(ISBLANK(C2),C2=0)), C2<G2), AND(NOT(AND(ISBLANK(D2),D2=0)), D2<G2)), "FAIL", "PASS")) -> FAIL | C2: =IF(R2,IF('9 points'!R3>0,'9 points'!R3,0),IF('5_13 points'!V3>0,'5_13 points'!V3,0)) -> 320 | D2: =IF(R2,IF('9 points'!S3>0,'9 points'!S3,0),IF('5_13 points'!W3>0,'5_13 points'!W3,0)) -> 320 | E2: =IF(R2,IF('9 points'!T3>0,'9 points'!T3,0),IF('5_13 points'!X3>0,'5_13 points'!X3,0)) -> 320 | F2: =(E2-C2)/2 -> 0 | G2: 321 | H2: 330 | K2: Panel model | L2: CX500 DLEDM | O2: Uniformity | Q2: UHD 9 @ 1/9 | R2: =OR(IF(Q2=X4,1,0),IF(Q2=X5,1,0),IF(Q2=X7,1,0),IF(Q2=X14,1,0),IF(Q2=X15,1,0),IF(Q2=X16,1,0),IF(Q2=X23,1,0),IF(Q2=X24,1,0),IF(Q2=X25,1,0)) -> TRUE | X2: HD 5 @ 1/9
A3: =IF(R2,"Brightness uniformity @1/9","Brightness uniformity @1/10") -> Brightness uniformity @1/9 | B3: =IF(OR(ISBLANK(C3),C3=0, ISBLANK(D3),D3=0), "NOT CHECKED", IF(OR(AND(NOT(AND(ISBLANK(C3),C3=0)), C3<G3), AND(NOT(AND(ISBLANK(D3),D3=0)), D3<G3)), "FAIL", "PASS")) -> FAIL | C3: =IF(R2,IF('9 points'!R4>0,'9 points'!R4,0),IF('5_13 points'!V4>0,'5_13 points'!V4,0)) -> 0.70019405 | D3: =IF(R2,IF('9 points'!S4>0,'9 points'!S4,0),IF('5_13 points'!W4>0,'5_13 points'!W4,0)) -> 0.70019405 | E3: =IF(R2,IF('9 points'!T4>0,'9 points'!T4,0),IF('5_13 points'!X4>0,'5_13 points'!X4,0)) -> 0.70019405 | F3: =(E3-C3)/2 -> 0 | G3: 0.71 | H3: 0.75 | O3: Uniformity | Q3: =IF(Q2=X8,X1,IF(Q2=X9,X2,IF(Q2=X10,X3,IF(Q2=X17,X11,IF(Q2=X18,X12,IF(Q2=X19,X13,IF(Q2=X26,X20,IF(Q2=X27,X21,IF(Q2=X28,X22,""))))))))) | X3: HD 5 @ 1/10
A4: =IF(R2,"","Brightness uniformity @1/4") | B4: =IF(A4="","",IFERROR(IF(K4,"PASS","FAIL"),K4)) | C4: =IF(R2,IF('9 points'!R5>0,'9 points'!R5,0),IF('5_13 points'!V5>0,'5_13 points'!V5,0)) -> 4433.874 | D4: =IF(R2,IF('9 points'!S5>0,'9 points'!S5,0),IF('5_13 points'!W5>0,'5_13 points'!W5,0)) -> 4433.874 | E4: =IF(R2,IF('9 points'!T5>0,'9 points'!T5,0),IF('5_13 points'!X5>0,'5_13 points'!X5,0)) -> 4433.874 | F4: =IFERROR((E4-C4)/2,"") -> 0 | O4: Panel to adjust PQ | Q4: =IF('9 points'!AA24<>0,'9 points'!AA24,IF('5_13 points'!AF24<>0,'5_13 points'!AF24,"")) -> 123 | X4: HD 9 @ 1/6
A5: Contrast by panel | B5: =IF(OR(ISBLANK(C5),C5=0, ISBLANK(D5),D5=0), "NOT CHECKED", IF(OR(AND(NOT(AND(ISBLANK(C5),C5=0)), C5<G5), AND(NOT(AND(ISBLANK(D5),D5=0)), D5<(H5*(1-$Q$1)))), "FAIL", "PASS")) -> PASS | C5: =IF(R2,IF('9 points'!R5>0,'9 points'!R5,0),IF('5_13 points'!V6>0,'5_13 points'!V6,0)) -> 4433.874 | D5: =IF(R2,IF('9 points'!S5>0,'9 points'!S5,0),IF('5_13 points'!W6>0,'5_13 points'!W6,0)) -> 4433.874 | E5: =IF(R2,IF('9 points'!T5>0,'9 points'!T5,0),IF('5_13 points'!X6>0,'5_13 points'!X6,0)) -> 4433.874 | F5: =(E5-C5)/2 -> 0 | G5: 3500 | H5: 4500 | X5: HD 9 @ 1/9
A6: Contrast by OC | B6: =IF(OR(ISBLANK(C6),C6=0, ISBLANK(D6),D6=0), "NOT CHECKED", IF(OR(AND(NOT(AND(ISBLANK(C6),C6=0)), C6<G6), AND(NOT(AND(ISBLANK(D6),D6=0)), D6<(H6*(1-$Q$1)))), "FAIL", "PASS")) -> FAIL | C6: =IF(R2,IF('9 points'!R5>0,'9 points'!R5,0),IF('5_13 points'!V6>0,'5_13 points'!V6,0)) -> 4433.874 | D6: =IF(R2,IF('9 points'!S5>0,'9 points'!S5,0),IF('5_13 points'!W6>0,'5_13 points'!W6,0)) -> 4433.874 | E6: =IF(R2,IF('9 points'!T5>0,'9 points'!T5,0),IF('5_13 points'!X6>0,'5_13 points'!X6,0)) -> 4433.874 | F6: =(E6-C6)/2 -> 0 | G6: 3500 | H6: 5000 | X6: HD 9 @ 1/10
A7: Color gamut | B7: =IF(OR(ISBLANK(C7),C7=0, ISBLANK(D7),D7=0), "NOT CHECKED", IF(OR(AND(NOT(AND(ISBLANK(C7),C7=0)), C7<G7), AND(NOT(AND(ISBLANK(D7),D7=0)), D7<G7)), "FAIL", "PASS")) -> PASS | C7: =IF(R2,IF('9 points'!R6>0,'9 points'!R6,0),IF('5_13 points'!V7>0,'5_13 points'!V7,0)) -> 0.71718505 | D7: =IF(R2,IF('9 points'!S6>0,'9 points'!S6,0),IF('5_13 points'!W7>0,'5_13 points'!W7,0)) -> 0.71718505 | E7: =IF(R2,IF('9 points'!T6>0,'9 points'!T6,0),IF('5_13 points'!X7>0,'5_13 points'!X7,0)) -> 0.71718505 | F7: =(E7-C7)/2 -> 0 | G7: 0.7 | H7: 0.85 | X7: HD 13 @ 1/6
A8: Gamma | B8: =IF(OR(ISBLANK(C8),C8=0, ISBLANK(D8),D8=0), "NOT CHECKED", IF(OR(AND(NOT(ISBLANK(C8)), C8<G8), AND(NOT(ISBLANK(D8)), D8<(H8*(1-$Q$1)))), "FAIL", "PASS")) -> NOT CHECKED | C8: =IF(ISBLANK(Gamma!C6),"Not checked",IF(Gamma!AF24>0,"Adjusted poor","Good")) -> Not checked | X8: HD 13 @ 1/9
A9: Color temperature | B9: =IF(OR(ISBLANK(C9),C9=0,ISBLANK(D9),D9=0,ISBLANK(E9),E9=0), "NOT CHECKED", IF(AND(C9>=G9,E9<=I9,AND(D9>=G9,D9<=I9),C9<=I9,E9>=G9), "PASS", "FAIL")) -> PASS | C9: =IF(R2,IF('9 points'!R8>0,'9 points'!R8,0),IF('5_13 points'!V9>0,'5_13 points'!V9,0)) -> 10292 | D9: =IF(R2,IF('9 points'!S8>0,'9 points'!S8,0),IF('5_13 points'!W9>0,'5_13 points'!W9,0)) -> 10292 | E9: =IF(R2,IF('9 points'!T8>0,'9 points'!T8,0),IF('5_13 points'!X9>0,'5_13 points'!X9,0)) -> 10292 | F9: =(E9-C9)/2 -> 0 | G9: =H9-J9 -> 7892 | H9: 9892 | I9: =H9+J9 -> 11892 | J9: 2000 | X9: HD 13 @ 1/10
A10: Tint uniformity | B10: =IF(OR(ISBLANK(C10),C10=0, ISBLANK(D10),D10=0), "NOT CHECKED", IF(OR(AND(NOT(ISBLANK(C10)), C10<G10), AND(NOT(ISBLANK(D10)), D10<(H10*(1-$Q$1)))), "FAIL", "PASS")) -> NOT CHECKED | C10: =IF(ISBLANK(Gamma!B6),"Not checked",IF(Gamma!AC24>0,"Adjusted poor","Good")) -> Not checked | X10: FHD 5 @ 1/6
A11: Red X | B11: =IF(OR(ISBLANK(C11),C11=0,ISBLANK(D11),D11=0,ISBLANK(E11),E11=0), "NOT CHECKED", IF(AND(C11>=G11,E11<=I11,AND(D11>=G11,D11<=I11),C11<=I11,E11>=G11), "PASS", "FAIL")) -> PASS | C11: =IF($R$2,IF('9 points'!R11>0,'9 points'!R11,0),IF('5_13 points'!V12>0,'5_13 points'!V12,0)) -> 0.636 | D11: =IF($R$2,IF('9 points'!S11>0,'9 points'!S11,0),IF('5_13 points'!W12>0,'5_13 points'!W12,0)) -> 0.636 | E11: =IF($R$2,IF('9 points'!T11>0,'9 points'!T11,0),IF('5_13 points'!X12>0,'5_13 points'!X12,0)) -> 0.636 | F11: =(E11-C11)/2 -> 0 | G11: =H11-J11 -> 0.57 | H11: 0.66 | I11: =H11+J11 -> 0.75 | J11: 0.09 | X11: FHD 5 @ 1/9
A12: Red Y | B12: =IF(OR(ISBLANK(C12),C12=0,ISBLANK(D12),D12=0,ISBLANK(E12),E12=0), "NOT CHECKED", IF(AND(C12>=G12,E12<=I12,AND(D12>=G12,D12<=I12),C12<=I12,E12>=G12), "PASS", "FAIL")) -> PASS | C12: =IF($R$2,IF('9 points'!R12>0,'9 points'!R12,0),IF('5_13 points'!V13>0,'5_13 points'!V13,0)) -> 0.329 | D12: =IF($R$2,IF('9 points'!S12>0,'9 points'!S12,0),IF('5_13 points'!W13>0,'5_13 points'!W13,0)) -> 0.329 | E12: =IF($R$2,IF('9 points'!T12>0,'9 points'!T12,0),IF('5_13 points'!X13>0,'5_13 points'!X13,0)) -> 0.329 | F12: =(E12-C12)/2 -> 0 | G12: =H12-J12 -> 0.22 | H12: 0.31 | I12: =H12+J12 -> 0.4 | J12: 0.09 | X12: FHD 5 @ 1/10
A13: Green X | B13: =IF(OR(ISBLANK(C13),C13=0,ISBLANK(D13),D13=0,ISBLANK(E13),E13=0), "NOT CHECKED", IF(AND(C13>=G13,E13<=I13,AND(D13>=G13,D13<=I13),C13<=I13,E13>=G13), "PASS", "FAIL")) -> PASS | C13: =IF($R$2,IF('9 points'!R13>0,'9 points'!R13,0),IF('5_13 points'!V14>0,'5_13 points'!V14,0)) -> 0.311 | D13: =IF($R$2,IF('9 points'!S13>0,'9 points'!S13,0),IF('5_13 points'!W14>0,'5_13 points'!W14,0)) -> 0.311 | E13: =IF($R$2,IF('9 points'!T13>0,'9 points'!T13,0),IF('5_13 points'!X14>0,'5_13 points'!X14,0)) -> 0.311 | F13: =(E13-C13)/2 -> 0 | G13: =H13-J13 -> 0.19 | H13: 0.28 | I13: =H13+J13 -> 0.37 | J13: 0.09 | X13: FHD 9 @ 1/6
A14: Green Y | B14: =IF(OR(ISBLANK(C14),C14=0,ISBLANK(D14),D14=0,ISBLANK(E14),E14=0), "NOT CHECKED", IF(AND(C14>=G14,E14<=I14,AND(D14>=G14,D14<=I14),C14<=I14,E14>=G14), "PASS", "FAIL")) -> PASS | C14: =IF($R$2,IF('9 points'!R14>0,'9 points'!R14,0),IF('5_13 points'!V15>0,'5_13 points'!V15,0)) -> 0.615 | D14: =IF($R$2,IF('9 points'!S14>0,'9 points'!S14,0),IF('5_13 points'!W15>0,'5_13 points'!W15,0)) -> 0.615 | E14: =IF($R$2,IF('9 points'!T14>0,'9 points'!T14,0),IF('5_13 points'!X15>0,'5_13 points'!X15,0)) -> 0.615 | F14: =(E14-C14)/2 -> 0 | G14: =H14-J14 -> 0.57 | H14: 0.66 | I14: =H14+J14 -> 0.75 | J14: 0.09 | X14: FHD 9 @ 1/9
A15: Blue X | B15: =IF(OR(ISBLANK(C15),C15=0,ISBLANK(D15),D15=0,ISBLANK(E15),E15=0), "NOT CHECKED", IF(AND(C15>=G15,E15<=I15,AND(D15>=G15,D15<=I15),C15<=I15,E15>=G15), "PASS", "FAIL")) -> PASS | C15: =IF($R$2,IF('9 points'!R15>0,'9 points'!R15,0),IF('5_13 points'!V16>0,'5_13 points'!V16,0)) -> 0.156 | D15: =IF($R$2,IF('9 points'!S15>0,'9 points'!S15,0),IF('5_13 points'!W16>0,'5_13 points'!W16,0)) -> 0.156 | E15: =IF($R$2,IF('9 points'!T15>0,'9 points'!T15,0),IF('5_13 points'!X16>0,'5_13 points'!X16,0)) -> 0.156 | F15: =(E15-C15)/2 -> 0 | G15: =H15-J15 -> 0.065 | H15: 0.155 | I15: =H15+J15 -> 0.245 | J15: 0.09 | X15: FHD 9 @ 1/10
A16: Blue Y | B16: =IF(OR(ISBLANK(C16),C16=0,ISBLANK(D16),D16=0,ISBLANK(E16),E16=0), "NOT CHECKED", IF(AND(C16>=G16,E16<=I16,AND(D16>=G16,D16<=I16),C16<=I16,E16>=G16), "PASS", "FAIL")) -> PASS | C16: =IF($R$2,IF('9 points'!R16>0,'9 points'!R16,0),IF('5_13 points'!V17>0,'5_13 points'!V17,0)) -> 0.049 | D16: =IF($R$2,IF('9 points'!S16>0,'9 points'!S16,0),IF('5_13 points'!W17>0,'5_13 points'!W17,0)) -> 0.049 | E16: =IF($R$2,IF('9 points'!T16>0,'9 points'!T16,0),IF('5_13 points'!X17>0,'5_13 points'!X17,0)) -> 0.049 | F16: =(E16-C16)/2 -> 0 | G16: =H16-J16 -> -0.035 | H16: 0.055 | I16: =H16+J16 -> 0.145 | J16: 0.09 | X16: FHD 13 @ 1/6
A17: White X | B17: =IF(OR(ISBLANK(C17),C17=0,ISBLANK(D17),D17=0,ISBLANK(E17),E17=0), "NOT CHECKED", IF(AND(C17>=G17,E17<=I17,AND(D17>=G17,D17<=I17),C17<=I17,E17>=G17), "PASS", "FAIL")) -> PASS | C17: =IF(R2,IF('9 points'!R9>0,'9 points'!R9,0),IF('5_13 points'!V10>0,'5_13 points'!V10,0)) -> 0.282 | D17: =IF(R2,IF('9 points'!S9>0,'9 points'!S9,0),IF('5_13 points'!W10>0,'5_13 points'!W10,0)) -> 0.282 | E17: =IF(R2,IF('9 points'!T9>0,'9 points'!T9,0),IF('5_13 points'!X10>0,'5_13 points'!X10,0)) -> 0.282 | F17: =(E17-C17)/2 -> 0 | G17: =H17-J17 -> 0.19 | H17: 0.28 | I17: =H17+J17 -> 0.37 | J17: 0.09 | X17: FHD 13 @ 1/9
A18: White Y | B18: =IF(OR(ISBLANK(C18),C18=0,ISBLANK(D18),D18=0,ISBLANK(E18),E18=0), "NOT CHECKED", IF(AND(C18>=G18,E18<=I18,AND(D18>=G18,D18<=I18),C18<=I18,E18>=G18), "PASS", "FAIL")) -> PASS | C18: =IF(R2,IF('9 points'!R10>0,'9 points'!R10,0),IF('5_13 points'!V11>0,'5_13 points'!V11,0)) -> 0.293 | D18: =IF(R2,IF('9 points'!S10>0,'9 points'!S10,0),IF('5_13 points'!W11>0,'5_13 points'!W11,0)) -> 0.293 | E18: =IF(R2,IF('9 points'!T10>0,'9 points'!T10,0),IF('5_13 points'!X11>0,'5_13 points'!X11,0)) -> 0.293 | F18: =(E18-C18)/2 -> 0 | G18: =H18-J18 -> 0.2 | H18: 0.29 | I18: =H18+J18 -> 0.38 | J18: 0.09 | X18: FHD 13 @ 1/10
X19: UHD 5 @ 1/6
M20: NTSC 1953 | O20: sRGB | Q20: =H1 -> IIS | S20: Measured | X20: UHD 5 @ 1/9
M21: x | N21: y | O21: x | P21: y | Q21: x | R21: y | S21: x | T21: y | U21: x | V21: y | X21: UHD 5 @ 1/10
M22: =IF(K23,0.674,0) -> 0.674 | N22: =IF(K23,0.326,0) -> 0.326 | O22: =IF(K25,0.64,0) -> 0 | P22: =IF(K25,0.33,0) -> 0 | Q22: =IF(K27,H11,0) -> 0.66 | R22: =IF(K27,H12,0) -> 0.31 | S22: =IF(K29,D11,0) -> 0.636 | T22: =IF(K29,D12,0) -> 0.329 | X22: UHD 9 @ 1/6
K23: TRUE | M23: =IF(K23,0.218,0) -> 0.218 | N23: =IF(K23,0.712,0) -> 0.712 | O23: =IF(K25,0.3,0) -> 0 | P23: =IF(K25,0.6,0) -> 0 | Q23: =IF(K27,H13,0) -> 0.28 | R23: =IF(K27,H14,0) -> 0.66 | S23: =IF(K29,D13,0) -> 0.311 | T23: =IF(K29,D14,0) -> 0.615 | X23: UHD 9 @ 1/9
M24: =IF(K23,0.14,0) -> 0.14 | N24: =IF(K23,0.08,0) -> 0.08 | O24: =IF(K25,0.15,0) -> 0 | P24: =IF(K25,0.06,0) -> 0 | Q24: =IF(K27,H15,0) -> 0.155 | R24: =IF(K27,H16,0) -> 0.055 | S24: =IF(K29,D15,0) -> 0.156 | T24: =IF(K29,D16,0) -> 0.049 | X24: UHD 9 @ 1/10
K25: FALSE | M25: =IF(K23,0.674,0) -> 0.674 | N25: =IF(K23,0.326,0) -> 0.326 | O25: =IF(K25,0.64,0) -> 0 | P25: =IF(K25,0.33,0) -> 0 | Q25: =IF(K27,Q22,0) -> 0.66 | R25: =IF(K27,R22,0) -> 0.31 | S25: =IF(K29,S22,0) -> 0.636 | T25: =IF(K29,T22,0) -> 0.329 | U25: =U22 -> 0 | V25: =V22 -> 0 | X25: UHD 13 @ 1/6
M26: % Color | N26: =(0.5*ABS(M22*N23-M23*N22+M23*N24-M24*N23+M24*N22-M22*N24)) -> 0.15915 | Q26: sRGB | R26: =(0.5*ABS(Q22*R23-Q23*R22+Q23*R24-Q24*R23+Q24*R22-Q22*R24)/$N26)/$P27 -> #DIV/0! | S26: sRGB | T26: =(0.5*ABS(S22*T23-S23*T22+S23*T24-S24*T23+S24*T22-S22*T24)/$N26)/$P27 -> #DIV/0! | U26: sRGB | V26: =(0.5*ABS(U22*V23-U23*V22+U23*V24-U24*V23+U24*V22-U22*V24)/$N26)/$P27 -> #DIV/0! | X26: UHD 13 @ 1/9
K27: TRUE | M27: % NTSC | N27: =(0.5*ABS(M22*N23-M23*N22+M23*N24-M24*N23+M24*N22-M22*N24)/$N26) -> 1 | P27: =(0.5*ABS(O22*P23-O23*P22+O23*P24-O24*P23+O24*P22-O22*P24)/$N26) -> 0 | Q27: NTSC | R27: =(0.5*ABS(Q22*R23-Q23*R22+Q23*R24-Q24*R23+Q24*R22-Q22*R24)/$N26) -> 0.85972353 | S27: NTSC | T27: =(0.5*ABS(S22*T23-S23*T22+S23*T24-S24*T23+S24*T22-S22*T24)/$N26) -> 0.71718505 | U27: NTSC | V27: =(0.5*ABS(U22*V23-U23*V22+U23*V24-U24*V23+U24*V22-U22*V24)/$N26) -> 0 | X27: UHD 13 @ 1/10
K29: TRUE

Sheet Gamma
B1: Normal | D1: Warm | F1: Cool | H1: User | J1: IRE Normal | M1: IRE Warm | P1: IRE Cool | S1: 9300 | T1: 6500 | U1: 11000
A2: White | B2: Temp | C2: Brightness | D2: Temp | E2: Brightness | F2: Temp | G2: Brightness | H2: Temp | I2: Brightness | J2: Min | K2: Norm | L2: Max | M2: Min | N2: Norm | O2: Max | P2: Min | Q2: Norm | R2: Max | S2: =IF(ABS(B23-S1)<500,B23,S1) -> 9300 | T2: =IF(ABS(D23-T1)<500,D23,T1) -> 6500 | U2: =IF(ABS(F23-U1)<1000,F23,U1) -> 11000
A3: 0 | J3: =$J$25*A3^$J$24 -> 0 | K3: =$K$25*A3^$K$24 -> 0 | L3: =$L$25*A3^$L$24 -> 0 | M3: =$M$25*A3^$M$24 -> 0 | N3: =$N$25*A3^$N$24 -> 0 | O3: =$O$25*A3^$O$24 -> 0 | P3: =$P$25*A3^$P$24 -> 0 | Q3: =$Q$25*A3^$Q$24 -> 0 | R3: =$R$25*A3^$R$24 -> 0 | S3: =S$2 -> 9300 | T3: =T$2 -> 6500 | U3: =U$2 -> 11000
A4: =A3+5 -> 5 | J4: =$J$25*A4^$J$24 -> 0 | K4: =$K$25*A4^$K$24 -> 0 | L4: =$L$25*A4^$L$24 -> 0 | M4: =$M$25*A4^$M$24 -> 0 | N4: =$N$25*A4^$N$24 -> 0 | O4: =$O$25*A4^$O$24 -> 0 | P4: =$P$25*A4^$P$24 -> 0 | Q4: =$Q$25*A4^$Q$24 -> 0 | R4: =$R$25*A4^$R$24 -> 0 | S4: =S$2 -> 9300 | T4: =T$2 -> 6500 | U4: =U$2 -> 11000 | V4: 2000 | W4: =S4-V4 -> 7300 | X4: =S4+V4 -> 11300 | Y4: =T4-V4*1.5 -> 3500 | Z4: =T4+V4*1.5 -> 9500 | AA4: =U4-V4*2 -> 7000 | AB4: =U4+V4*2 -> 15000 | AC4: =IF(B4>X4,1,IF(B4<W4,1,0)) -> 1 | AD4: =IF(D4>Z4,1,IF(D4<Y4,1,0)) -> 1 | AE4: =IF(G4>AB4,1,IF(G4<AA4,1,0)) -> 1 | AF4: =IF(C4>L4,1,IF(C4<J4,1,0)) -> 0 | AG4: =IF(E4>O4,1,IF(E4<M4,1,0)) -> 0 | AH4: =IF(G4>R4,1,IF(G4<P4,1,0)) -> 0
A5: =A4+5 -> 10 | J5: =$J$25*A5^$J$24 -> 0 | K5: =$K$25*A5^$K$24 -> 0 | L5: =$L$25*A5^$L$24 -> 0 | M5: =$M$25*A5^$M$24 -> 0 | N5: =$N$25*A5^$N$24 -> 0 | O5: =$O$25*A5^$O$24 -> 0 | P5: =$P$25*A5^$P$24 -> 0 | Q5: =$Q$25*A5^$Q$24 -> 0 | R5: =$R$25*A5^$R$24 -> 0 | S5: =S$2 -> 9300 | T5: =T$2 -> 6500 | U5: =U$2 -> 11000 | V5: 1000 | W5: =S5-V5 -> 8300 | X5: =S5+V5 -> 10300 | Y5: =T5-V5*1.5 -> 5000 | Z5: =T5+V5*1.5 -> 8000 | AA5: =U5-V5*2 -> 9000 | AB5: =U5+V5*2 -> 13000 | AC5: =IF(B5>X5,1,IF(B5<W5,1,0)) -> 1 | AD5: =IF(D5>Z5,1,IF(D5<Y5,1,0)) -> 1 | AE5: =IF(G5>AB5,1,IF(G5<AA5,1,0)) -> 1 | AF5: =IF(C5>L5,1,IF(C5<J5,1,0)) -> 0 | AG5: =IF(E5>O5,1,IF(E5<M5,1,0)) -> 0 | AH5: =IF(G5>R5,1,IF(G5<P5,1,0)) -> 0
A6: =A5+5 -> 15 | J6: =$J$25*A6^$J$24 -> 0 | K6: =$K$25*A6^$K$24 -> 0 | L6: =$L$25*A6^$L$24 -> 0 | M6: =$M$25*A6^$M$24 -> 0 | N6: =$N$25*A6^$N$24 -> 0 | O6: =$O$25*A6^$O$24 -> 0 | P6: =$P$25*A6^$P$24 -> 0 | Q6: =$Q$25*A6^$Q$24 -> 0 | R6: =$R$25*A6^$R$24 -> 0 | S6: =S$2 -> 9300 | T6: =T$2 -> 6500 | U6: =U$2 -> 11000 | V6: 500 | W6: =S6-V6 -> 8800 | X6: =S6+V6 -> 9800 | Y6: =T6-V6*1.5 -> 5750 | Z6: =T6+V6*1.5 -> 7250 | AA6: =U6-V6*2 -> 10000 | AB6: =U6+V6*2 -> 12000 | AC6: =IF(B6>X6,1,IF(B6<W6,1,0)) -> 1 | AD6: =IF(D6>Z6,1,IF(D6<Y6,1,0)) -> 1 | AE6: =IF(G6>AB6,1,IF(G6<AA6,1,0)) -> 1 | AF6: =IF(C6>L6,1,IF(C6<J6,1,0)) -> 0 | AG6: =IF(E6>O6,1,IF(E6<M6,1,0)) -> 0 | AH6: =IF(G6>R6,1,IF(G6<P6,1,0)) -> 0
A7: =A6+5 -> 20 | J7: =$J$25*A7^$J$24 -> 0 | K7: =$K$25*A7^$K$24 -> 0 | L7: =$L$25*A7^$L$24 -> 0 | M7: =$M$25*A7^$M$24 -> 0 | N7: =$N$25*A7^$N$24 -> 0 | O7: =$O$25*A7^$O$24 -> 0 | P7: =$P$25*A7^$P$24 -> 0 | Q7: =$Q$25*A7^$Q$24 -> 0 | R7: =$R$25*A7^$R$24 -> 0 | S7: =S$2 -> 9300 | T7: =T$2 -> 6500 | U7: =U$2 -> 11000 | V7: 100 | W7: =S7-V7 -> 9200 | X7: =S7+V7 -> 9400 | Y7: =T7-V7*1.5 -> 6350 | Z7: =T7+V7*1.5 -> 6650 | AA7: =U7-V7*2 -> 10800 | AB7: =U7+V7*2 -> 11200 | AC7: =IF(B7>X7,1,IF(B7<W7,1,0)) -> 1 | AD7: =IF(D7>Z7,1,IF(D7<Y7,1,0)) -> 1 | AE7: =IF(G7>AB7,1,IF(G7<AA7,1,0)) -> 1 | AF7: =IF(C7>L7,1,IF(C7<J7,1,0)) -> 0 | AG7: =IF(E7>O7,1,IF(E7<M7,1,0)) -> 0 | AH7: =IF(G7>R7,1,IF(G7<P7,1,0)) -> 0
A8: =A7+5 -> 25 | J8: =$J$25*A8^$J$24 -> 0 | K8: =$K$25*A8^$K$24 -> 0 | L8: =$L$25*A8^$L$24 -> 0 | M8: =$M$25*A8^$M$24 -> 0 | N8: =$N$25*A8^$N$24 -> 0 | O8: =$O$25*A8^$O$24 -> 0 | P8: =$P$25*A8^$P$24 -> 0 | Q8: =$Q$25*A8^$Q$24 -> 0 | R8: =$R$25*A8^$R$24 -> 0 | S8: =S$2 -> 9300 | T8: =T$2 -> 6500 | U8: =U$2 -> 11000 | V8: 100 | W8: =S8-V8 -> 9200 | X8: =S8+V8 -> 9400 | Y8: =T8-V8*1.5 -> 6350 | Z8: =T8+V8*1.5 -> 6650 | AA8: =U8-V8*2 -> 10800 | AB8: =U8+V8*2 -> 11200 | AC8: =IF(B8>X8,1,IF(B8<W8,1,0)) -> 1 | AD8: =IF(D8>Z8,1,IF(D8<Y8,1,0)) -> 1 | AE8: =IF(G8>AB8,1,IF(G8<AA8,1,0)) -> 1 | AF8: =IF(C8>L8,1,IF(C8<J8,1,0)) -> 0 | AG8: =IF(E8>O8,1,IF(E8<M8,1,0)) -> 0 | AH8: =IF(G8>R8,1,IF(G8<P8,1,0)) -> 0
A9: =A8+5 -> 30 | J9: =$J$25*A9^$J$24 -> 0 | K9: =$K$25*A9^$K$24 -> 0 | L9: =$L$25*A9^$L$24 -> 0 | M9: =$M$25*A9^$M$24 -> 0 | N9: =$N$25*A9^$N$24 -> 0 | O9: =$O$25*A9^$O$24 -> 0 | P9: =$P$25*A9^$P$24 -> 0 | Q9: =$Q$25*A9^$Q$24 -> 0 | R9: =$R$25*A9^$R$24 -> 0 | S9: =S$2 -> 9300 | T9: =T$2 -> 6500 | U9: =U$2 -> 11000 | V9: 100 | W9: =S9-V9 -> 9200 | X9: =S9+V9 -> 9400 | Y9: =T9-V9*1.5 -> 6350 | Z9: =T9+V9*1.5 -> 6650 | AA9: =U9-V9*2 -> 10800 | AB9: =U9+V9*2 -> 11200 | AC9: =IF(B9>X9,1,IF(B9<W9,1,0)) -> 1 | AD9: =IF(D9>Z9,1,IF(D9<Y9,1,0)) -> 1 | AE9: =IF(G9>AB9,1,IF(G9<AA9,1,0)) -> 1 | AF9: =IF(C9>L9,1,IF(C9<J9,1,0)) -> 0 | AG9: =IF(E9>O9,1,IF(E9<M9,1,0)) -> 0 | AH9: =IF(G9>R9,1,IF(G9<P9,1,0)) -> 0
A10: =A9+5 -> 35 | J10: =$J$25*A10^$J$24 -> 0 | K10: =$K$25*A10^$K$24 -> 0 | L10: =$L$25*A10^$L$24 -> 0 | M10: =$M$25*A10^$M$24 -> 0 | N10: =$N$25*A10^$N$24 -> 0 | O10: =$O$25*A10^$O$24 -> 0 | P10: =$P$25*A10^$P$24 -> 0 | Q10: =$Q$25*A10^$Q$24 -> 0 | R10: =$R$25*A10^$R$24 -> 0 | S10: =S$2 -> 9300 | T10: =T$2 -> 6500 | U10: =U$2 -> 11000 | V10: 100 | W10: =S10-V10 -> 9200 | X10: =S10+V10 -> 9400 | Y10: =T10-V10*1.5 -> 6350 | Z10: =T10+V10*1.5 -> 6650 | AA10: =U10-V10*2 -> 10800 | AB10: =U10+V10*2 -> 11200 | AC10: =IF(B10>X10,1,IF(B10<W10,1,0)) -> 1 | AD10: =IF(D10>Z10,1,IF(D10<Y10,1,0)) -> 1 | AE10: =IF(G10>AB10,1,IF(G10<AA10,1,0)) -> 1 | AF10: =IF(C10>L10,1,IF(C10<J10,1,0)) -> 0 | AG10: =IF(E10>O10,1,IF(E10<M10,1,0)) -> 0 | AH10: =IF(G10>R10,1,IF(G10<P10,1,0)) -> 0
A11: =A10+5 -> 40 | J11: =$J$25*A11^$J$24 -> 0 | K11: =$K$25*A11^$K$24 -> 0 | L11: =$L$25*A11^$L$24 -> 0 | M11: =$M$25*A11^$M$24 -> 0 | N11: =$N$25*A11^$N$24 -> 0 | O11: =$O$25*A11^$O$24 -> 0 | P11: =$P$25*A11^$P$24 -> 0 | Q11: =$Q$25*A11^$Q$24 -> 0 | R11: =$R$25*A11^$R$24 -> 0 | S11: =S$2 -> 9300 | T11: =T$2 -> 6500 | U11: =U$2 -> 11000 | V11: 100 | W11: =S11-V11 -> 9200 | X11: =S11+V11 -> 9400 | Y11: =T11-V11*1.5 -> 6350 | Z11: =T11+V11*1.5 -> 6650 | AA11: =U11-V11*2 -> 10800 | AB11: =U11+V11*2 -> 11200 | AC11: =IF(B11>X11,1,IF(B11<W11,1,0)) -> 1 | AD11: =IF(D11>Z11,1,IF(D11<Y11,1,0)) -> 1 | AE11: =IF(G11>AB11,1,IF(G11<AA11,1,0)) -> 1 | AF11: =IF(C11>L11,1,IF(C11<J11,1,0)) -> 0 | AG11: =IF(E11>O11,1,IF(E11<M11,1,0)) -> 0 | AH11: =IF(G11>R11,1,IF(G11<P11,1,0)) -> 0
A12: =A11+5 -> 45 | J12: =$J$25*A12^$J$24 -> 0 | K12: =$K$25*A12^$K$24 -> 0 | L12: =$L$25*A12^$L$24 -> 0 | M12: =$M$25*A12^$M$24 -> 0 | N12: =$N$25*A12^$N$24 -> 0 | O12: =$O$25*A12^$O$24 -> 0 | P12: =$P$25*A12^$P$24 -> 0 | Q12: =$Q$25*A12^$Q$24 -> 0 | R12: =$R$25*A12^$R$24 -> 0 | S12: =S$2 -> 9300 | T12: =T$2 -> 6500 | U12: =U$2 -> 11000 | V12: 100 | W12: =S12-V12 -> 9200 | X12: =S12+V12 -> 9400 | Y12: =T12-V12*1.5 -> 6350 | Z12: =T12+V12*1.5 -> 6650 | AA12: =U12-V12*2 -> 10800 | AB12: =U12+V12*2 -> 11200 | AC12: =IF(B12>X12,1,IF(B12<W12,1,0)) -> 1 | AD12: =IF(D12>Z12,1,IF(D12<Y12,1,0)) -> 1 | AE12: =IF(G12>AB12,1,IF(G12<AA12,1,0)) -> 1 | AF12: =IF(C12>L12,1,IF(C12<J12,1,0)) -> 0 | AG12: =IF(E12>O12,1,IF(E12<M12,1,0)) -> 0 | AH12: =IF(G12>R12,1,IF(G12<P12,1,0)) -> 0
A13: =A12+5 -> 50 | J13: =$J$25*A13^$J$24 -> 0 | K13: =$K$25*A13^$K$24 -> 0 | L13: =$L$25*A13^$L$24 -> 0 | M13: =$M$25*A13^$M$24 -> 0 | N13: =$N$25*A13^$N$24 -> 0 | O13: =$O$25*A13^$O$24 -> 0 | P13: =$P$25*A13^$P$24 -> 0 | Q13: =$Q$25*A13^$Q$24 -> 0 | R13: =$R$25*A13^$R$24 -> 0 | S13: =S$2 -> 9300 | T13: =T$2 -> 6500 | U13: =U$2 -> 11000 | V13: 100 | W13: =S13-V13 -> 9200 | X13: =S13+V13 -> 9400 | Y13: =T13-V13*1.5 -> 6350 | Z13: =T13+V13*1.5 -> 6650 | AA13: =U13-V13*2 -> 10800 | AB13: =U13+V13*2 -> 11200 | AC13: =IF(B13>X13,1,IF(B13<W13,1,0)) -> 1 | AD13: =IF(D13>Z13,1,IF(D13<Y13,1,0)) -> 1 | AE13: =IF(G13>AB13,1,IF(G13<AA13,1,0)) -> 1 | AF13: =IF(C13>L13,1,IF(C13<J13,1,0)) -> 0 | AG13: =IF(E13>O13,1,IF(E13<M13,1,0)) -> 0 | AH13: =IF(G13>R13,1,IF(G13<P13,1,0)) -> 0
A14: =A13+5 -> 55 | J14: =$J$25*A14^$J$24 -> 0 | K14: =$K$25*A14^$K$24 -> 0 | L14: =$L$25*A14^$L$24 -> 0 | M14: =$M$25*A14^$M$24 -> 0 | N14: =$N$25*A14^$N$24 -> 0 | O14: =$O$25*A14^$O$24 -> 0 | P14: =$P$25*A14^$P$24 -> 0 | Q14: =$Q$25*A14^$Q$24 -> 0 | R14: =$R$25*A14^$R$24 -> 0 | S14: =S$2 -> 9300 | T14: =T$2 -> 6500 | U14: =U$2 -> 11000 | V14: 100 | W14: =S14-V14 -> 9200 | X14: =S14+V14 -> 9400 | Y14: =T14-V14*1.5 -> 6350 | Z14: =T14+V14*1.5 -> 6650 | AA14: =U14-V14*2 -> 10800 | AB14: =U14+V14*2 -> 11200 | AC14: =IF(B14>X14,1,IF(B14<W14,1,0)) -> 1 | AD14: =IF(D14>Z14,1,IF(D14<Y14,1,0)) -> 1 | AE14: =IF(G14>AB14,1,IF(G14<AA14,1,0)) -> 1 | AF14: =IF(C14>L14,1,IF(C14<J14,1,0)) -> 0 | AG14: =IF(E14>O14,1,IF(E14<M14,1,0)) -> 0 | AH14: =IF(G14>R14,1,IF(G14<P14,1,0)) -> 0
A15: =A14+5 -> 60 | J15: =$J$25*A15^$J$24 -> 0 | K15: =$K$25*A15^$K$24 -> 0 | L15: =$L$25*A15^$L$24 -> 0 | M15: =$M$25*A15^$M$24 -> 0 | N15: =$N$25*A15^$N$24 -> 0 | O15: =$O$25*A15^$O$24 -> 0 | P15: =$P$25*A15^$P$24 -> 0 | Q15: =$Q$25*A15^$Q$24 -> 0 | R15: =$R$25*A15^$R$24 -> 0 | S15: =S$2 -> 9300 | T15: =T$2 -> 6500 | U15: =U$2 -> 11000 | V15: 100 | W15: =S15-V15 -> 9200 | X15: =S15+V15 -> 9400 | Y15: =T15-V15*1.5 -> 6350 | Z15: =T15+V15*1.5 -> 6650 | AA15: =U15-V15*2 -> 10800 | AB15: =U15+V15*2 -> 11200 | AC15: =IF(B15>X15,1,IF(B15<W15,1,0)) -> 1 | AD15: =IF(D15>Z15,1,IF(D15<Y15,1,0)) -> 1 | AE15: =IF(G15>AB15,1,IF(G15<AA15,1,0)) -> 1 | AF15: =IF(C15>L15,1,IF(C15<J15,1,0)) -> 0 | AG15: =IF(E15>O15,1,IF(E15<M15,1,0)) -> 0 | AH15: =IF(G15>R15,1,IF(G15<P15,1,0)) -> 0
... A23: =A22+5 -> 100 | J23: =$J$25*A23^$J$24 -> 0 | K23: =$K$25*A23^$K$24 -> 0 | L23: =$L$25*A23^$L$24 -> 0 | M23: =$M$25*A23^$M$24 -> 0 | N23: =$N$25*A23^$N$24 -> 0 | O23: =$O$25*A23^$O$24 -> 0 | P23: =$P$25*A23^$P$24 -> 0 | Q23: =$Q$25*A23^$Q$24 -> 0 | R23: =$R$25*A23^$R$24 -> 0 | S23: =S$2 -> 9300 | T23: =T$2 -> 6500 | U23: =U$2 -> 11000 | V23: 100 | W23: =S23-V23 -> 9200 | X23: =S23+V23 -> 9400 | Y23: =T23-V23*1.5 -> 6350 | Z23: =T23+V23*1.5 -> 6650 | AA23: =U23-V23*2 -> 10800 | AB23: =U23+V23*2 -> 11200 | AC23: =IF(B23>X23,1,IF(B23<W23,1,0)) -> 1 | AD23: =IF(D23>Z23,1,IF(D23<Y23,1,0)) -> 1 | AE23: =IF(G23>AB23,1,IF(G23<AA23,1,0)) -> 1 | AF23: =IF(C23>L23,1,IF(C23<J23,1,0)) -> 0 | AG23: =IF(E23>O23,1,IF(E23<M23,1,0)) -> 0 | AH23: =IF(G23>R23,1,IF(G23<P23,1,0)) -> 0
J24: 3 | K24: 2.2 | L24: 1.9 | M24: 3 | N24: 2.2 | O24: 1.9 | P24: 3 | Q24: 2.2 | R24: 1.9 | AC24: =SUM(AC4:AC23) -> 20 | AD24: =SUM(AD4:AD23) -> 20 | AE24: =SUM(AE4:AE23) -> 20 | AF24: =SUM(AF4:AF23) -> 0 | AG24: =SUM(AG4:AG23) -> 0 | AH24: =SUM(AH4:AH23) -> 0
J25: =C23/(100^J24) -> 0 | K25: =C23/(100^K24) -> 0 | L25: =C23/(100^L24) -> 0 | M25: =E23/(100^M24) -> 0 | N25: =E23/(100^N24) -> 0 | O25: =E23/(100^O24) -> 0 | P25: =G23/(100^P24) -> 0 | Q25: =G23/(100^Q24) -> 0 | R25: =G23/(100^R24) -> 0
F49: Normal
B50: Color temperature of Greyscale | E50: Normal | F50: Warm
F51: Cool | J51: Current | K51: 3,0 | L51: 2.2 | M51: 1.9
F52: User | J52: =IF($E$50=$B$1,C3,IF($E$50=$D$1,E3,IF($E$50=$F$1,G3,IF($E$50=$H$1,I3,"Wrong data")))) -> 0 | K52: =IF($E$50=$B$1,J3,IF($E$50=$D$1,M3,IF($E$50=$F$1,P3,IF($E$50=$H$1,S3,"Wrong data")))) -> 0 | L52: =IF($E$50=$B$1,K3,IF($E$50=$D$1,N3,IF($E$50=$F$1,Q3,IF($E$50=$H$1,T3,"Wrong data")))) -> 0 | M52: =IF($E$50=$B$1,L3,IF($E$50=$D$1,O3,IF($E$50=$F$1,R3,IF($E$50=$H$1,U3,"Wrong data")))) -> 0
J53: =IF($E$50=$B$1,C4,IF($E$50=$D$1,E4,IF($E$50=$F$1,G4,IF($E$50=$H$1,I4,"Wrong data")))) -> 0 | K53: =IF($E$50=$B$1,J4,IF($E$50=$D$1,M4,IF($E$50=$F$1,P4,IF($E$50=$H$1,S4,"Wrong data")))) -> 0 | L53: =IF($E$50=$B$1,K4,IF($E$50=$D$1,N4,IF($E$50=$F$1,Q4,IF($E$50=$H$1,T4,"Wrong data")))) -> 0 | M53: =IF($E$50=$B$1,L4,IF($E$50=$D$1,O4,IF($E$50=$F$1,R4,IF($E$50=$H$1,U4,"Wrong data")))) -> 0
J54: =IF($E$50=$B$1,C5,IF($E$50=$D$1,E5,IF($E$50=$F$1,G5,IF($E$50=$H$1,I5,"Wrong data")))) -> 0 | K54: =IF($E$50=$B$1,J5,IF($E$50=$D$1,M5,IF($E$50=$F$1,P5,IF($E$50=$H$1,S5,"Wrong data")))) -> 0 | L54: =IF($E$50=$B$1,K5,IF($E$50=$D$1,N5,IF($E$50=$F$1,Q5,IF($E$50=$H$1,T5,"Wrong data")))) -> 0 | M54: =IF($E$50=$B$1,L5,IF($E$50=$D$1,O5,IF($E$50=$F$1,R5,IF($E$50=$H$1,U5,"Wrong data")))) -> 0
J55: =IF($E$50=$B$1,C6,IF($E$50=$D$1,E6,IF($E$50=$F$1,G6,IF($E$50=$H$1,I6,"Wrong data")))) -> 0 | K55: =IF($E$50=$B$1,J6,IF($E$50=$D$1,M6,IF($E$50=$F$1,P6,IF($E$50=$H$1,S6,"Wrong data")))) -> 0 | L55: =IF($E$50=$B$1,K6,IF($E$50=$D$1,N6,IF($E$50=$F$1,Q6,IF($E$50=$H$1,T6,"Wrong data")))) -> 0 | M55: =IF($E$50=$B$1,L6,IF($E$50=$D$1,O6,IF($E$50=$F$1,R6,IF($E$50=$H$1,U6,"Wrong data")))) -> 0
J56: =IF($E$50=$B$1,C7,IF($E$50=$D$1,E7,IF($E$50=$F$1,G7,IF($E$50=$H$1,I7,"Wrong data")))) -> 0 | K56: =IF($E$50=$B$1,J7,IF($E$50=$D$1,M7,IF($E$50=$F$1,P7,IF($E$50=$H$1,S7,"Wrong data")))) -> 0 | L56: =IF($E$50=$B$1,K7,IF($E$50=$D$1,N7,IF($E$50=$F$1,Q7,IF($E$50=$H$1,T7,"Wrong data")))) -> 0 | M56: =IF($E$50=$B$1,L7,IF($E$50=$D$1,O7,IF($E$50=$F$1,R7,IF($E$50=$H$1,U7,"Wrong data")))) -> 0
J57: =IF($E$50=$B$1,C8,IF($E$50=$D$1,E8,IF($E$50=$F$1,G8,IF($E$50=$H$1,I8,"Wrong data")))) -> 0 | K57: =IF($E$50=$B$1,J8,IF($E$50=$D$1,M8,IF($E$50=$F$1,P8,IF($E$50=$H$1,S8,"Wrong data")))) -> 0 | L57: =IF($E$50=$B$1,K8,IF($E$50=$D$1,N8,IF($E$50=$F$1,Q8,IF($E$50=$H$1,T8,"Wrong data")))) -> 0 | M57: =IF($E$50=$B$1,L8,IF($E$50=$D$1,O8,IF($E$50=$F$1,R8,IF($E$50=$H$1,U8,"Wrong data")))) -> 0
J58: =IF($E$50=$B$1,C9,IF($E$50=$D$1,E9,IF($E$50=$F$1,G9,IF($E$50=$H$1,I9,"Wrong data")))) -> 0 | K58: =IF($E$50=$B$1,J9,IF($E$50=$D$1,M9,IF($E$50=$F$1,P9,IF($E$50=$H$1,S9,"Wrong data")))) -> 0 | L58: =IF($E$50=$B$1,K9,IF($E$50=$D$1,N9,IF($E$50=$F$1,Q9,IF($E$50=$H$1,T9,"Wrong data")))) -> 0 | M58: =IF($E$50=$B$1,L9,IF($E$50=$D$1,O9,IF($E$50=$F$1,R9,IF($E$50=$H$1,U9,"Wrong data")))) -> 0
J59: =IF($E$50=$B$1,C10,IF($E$50=$D$1,E10,IF($E$50=$F$1,G10,IF($E$50=$H$1,I10,"Wrong data")))) -> 0 | K59: =IF($E$50=$B$1,J10,IF($E$50=$D$1,M10,IF($E$50=$F$1,P10,IF($E$50=$H$1,S10,"Wrong data")))) -> 0 | L59: =IF($E$50=$B$1,K10,IF($E$50=$D$1,N10,IF($E$50=$F$1,Q10,IF($E$50=$H$1,T10,"Wrong data")))) -> 0 | M59: =IF($E$50=$B$1,L10,IF($E$50=$D$1,O10,IF($E$50=$F$1,R10,IF($E$50=$H$1,U10,"Wrong data")))) -> 0
J60: =IF($E$50=$B$1,C11,IF($E$50=$D$1,E11,IF($E$50=$F$1,G11,IF($E$50=$H$1,I11,"Wrong data")))) -> 0 | K60: =IF($E$50=$B$1,J11,IF($E$50=$D$1,M11,IF($E$50=$F$1,P11,IF($E$50=$H$1,S11,"Wrong data")))) -> 0 | L60: =IF($E$50=$B$1,K11,IF($E$50=$D$1,N11,IF($E$50=$F$1,Q11,IF($E$50=$H$1,T11,"Wrong data")))) -> 0 | M60: =IF($E$50=$B$1,L11,IF($E$50=$D$1,O11,IF($E$50=$F$1,R11,IF($E$50=$H$1,U11,"Wrong data")))) -> 0
J61: =IF($E$50=$B$1,C12,IF($E$50=$D$1,E12,IF($E$50=$F$1,G12,IF($E$50=$H$1,I12,"Wrong data")))) -> 0 | K61: =IF($E$50=$B$1,J12,IF($E$50=$D$1,M12,IF($E$50=$F$1,P12,IF($E$50=$H$1,S12,"Wrong data")))) -> 0 | L61: =IF($E$50=$B$1,K12,IF($E$50=$D$1,N12,IF($E$50=$F$1,Q12,IF($E$50=$H$1,T12,"Wrong data")))) -> 0 | M61: =IF($E$50=$B$1,L12,IF($E$50=$D$1,O12,IF($E$50=$F$1,R12,IF($E$50=$H$1,U12,"Wrong data")))) -> 0
J62: =IF($E$50=$B$1,C13,IF($E$50=$D$1,E13,IF($E$50=$F$1,G13,IF($E$50=$H$1,I13,"Wrong data")))) -> 0 | K62: =IF($E$50=$B$1,J13,IF($E$50=$D$1,M13,IF($E$50=$F$1,P13,IF($E$50=$H$1,S13,"Wrong data")))) -> 0 | L62: =IF($E$50=$B$1,K13,IF($E$50=$D$1,N13,IF($E$50=$F$1,Q13,IF($E$50=$H$1,T13,"Wrong data")))) -> 0 | M62: =IF($E$50=$B$1,L13,IF($E$50=$D$1,O13,IF($E$50=$F$1,R13,IF($E$50=$H$1,U13,"Wrong data")))) -> 0
J63: =IF($E$50=$B$1,C14,IF($E$50=$D$1,E14,IF($E$50=$F$1,G14,IF($E$50=$H$1,I14,"Wrong data")))) -> 0 | K63: =IF($E$50=$B$1,J14,IF($E$50=$D$1,M14,IF($E$50=$F$1,P14,IF($E$50=$H$1,S14,"Wrong data")))) -> 0 | L63: =IF($E$50=$B$1,K14,IF($E$50=$D$1,N14,IF($E$50=$F$1,Q14,IF($E$50=$H$1,T14,"Wrong data")))) -> 0 | M63: =IF($E$50=$B$1,L14,IF($E$50=$D$1,O14,IF($E$50=$F$1,R14,IF($E$50=$H$1,U14,"Wrong data")))) -> 0
J64: =IF($E$50=$B$1,C15,IF($E$50=$D$1,E15,IF($E$50=$F$1,G15,IF($E$50=$H$1,I15,"Wrong data")))) -> 0 | K64: =IF($E$50=$B$1,J15,IF($E$50=$D$1,M15,IF($E$50=$F$1,P15,IF($E$50=$H$1,S15,"Wrong data")))) -> 0 | L64: =IF($E$50=$B$1,K15,IF($E$50=$D$1,N15,IF($E$50=$F$1,Q15,IF($E$50=$H$1,T15,"Wrong data")))) -> 0 | M64: =IF($E$50=$B$1,L15,IF($E$50=$D$1,O15,IF($E$50=$F$1,R15,IF($E$50=$H$1,U15,"Wrong data")))) -> 0
... J72: =IF($E$50=$B$1,C23,IF($E$50=$D$1,E23,IF($E$50=$F$1,G23,IF($E$50=$H$1,I23,"Wrong data")))) -> 0 | K72: =IF($E$50=$B$1,J23,IF($E$50=$D$1,M23,IF($E$50=$F$1,P23,IF($E$50=$H$1,S23,"Wrong data")))) -> 0 | L72: =IF($E$50=$B$1,K23,IF($E$50=$D$1,N23,IF($E$50=$F$1,Q23,IF($E$50=$H$1,T23,"Wrong data")))) -> 0 | M72: =IF($E$50=$B$1,L23,IF($E$50=$D$1,O23,IF($E$50=$F$1,R23,IF($E$50=$H$1,U23,"Wrong data")))) -> 0

Sheet 9 points
A1: 1 | B1: SN | C1: 123 | G1: 11 | H1: SN
B2: HDMI | C2: =IF(Statistics!$R$2,Statistics!$Q$2,"Use '5/13 points' sheet !") -> UHD 9 @ 1/9 | H2: HDMI | I2: =IF(Statistics!$R$2,Statistics!$Q$2,"Use '5/13 points' sheet !") -> UHD 9 @ 1/9 | M2: =IF(Statistics!$R$2,CONCATENATE(IF(O2="","要测试九个点和白墙亮度; ",IF(O2,,"工厂模式白屏亮度不够, 再一次确认下; ")),IF(O3="","要测试白黑屏亮度; ",IF(O3,,"工厂模式黑屏亮度太大, 再一次确认下; ")),IF(O4="","要测试九个点亮度; ",IF(O4,,"9个白点之间的亮度差异太高, 再一次确认下; ")),IF(O5="","要测试四个颜色; ",IF(O5,,"3个红绿蓝颜色不太对的, 再一次确认下")),IF(F3>C7,"告诉Vova和工厂业务电视软件有大问题: 客人模式亮度不应该比工厂模式亮度还高","")),"不可以用这一页, 需要打开下一页‘5_13 points’!") | N2: =IF(Statistics!$R$2,CONCATENATE(IF(P2="","要测试九个点和白墙亮度; ",IF(P2,,"工厂模式白屏亮度不够, 再一次确认下; ")),IF(P3="","要测试白黑屏亮度; ",IF(P3,,"工厂模式黑屏亮度太大, 再一次确认下; ")),IF(P4="","要测试九个点亮度; ",IF(P4,,"9个白点之间的亮度差异太高, 再一次确认下; ")),IF(P5="","要测试四个颜色; ",IF(P5,,"3个红绿蓝颜色不太对的, 再一次确认下")),IF(G3>D7,"告诉Vova和工厂业务电视软件有大问题: 客人模式亮度不应该比工厂模式亮度还高","")),"不可以用这一页, 需要打开下一页‘5_13 points’!") -> 要测试九个点和白墙亮度; 要测试白黑屏亮度; 要测试九个点亮度; 要测试四个颜色; | O2: =IF(C7<1,"",IF(F6<Statistics!$G$2*(1-Statistics!$Q$1),FALSE,TRUE)) -> TRUE | P2: =IF(I7<1,"",IF(L6<Statistics!$G$2*(1-Statistics!$Q$1),FALSE,TRUE)) | R2: MIN | S2: TYP | T2: MAX | U2: UF | V2: CR | W2: CG | Z2: CT | AA2: SN
C3: 218.7 | D3: 264.3 | E3: 216.5 | F3: =MAX(C3:E5) -> 309.2 | L3: =MAX(I3:K5) -> 0 | O3: =IF(D7=0,"",IF(F7<Statistics!$G$5*(1-Statistics!$Q$1),FALSE,TRUE)) -> TRUE | P3: =IF(J7=0,"",IF(L7<Statistics!$G$5*(1-Statistics!$Q$1),FALSE,TRUE)) | Q3: Brightness | R3: {=MIN(IF(X3:Y12>0,X3:Y12,""))} -> 320 | S3: =IFERROR(AVERAGEIF(X3:Y12,">0"),0) -> 320 | T3: =MAX(X3:Y12) -> 320 | U3: =IF(F5=0,"",F5) -> 0.70019405 | V3: =IF(F7=0,"",F7) -> 4433.874 | W3: =IF(F8=0,"",F8) -> 0.71718505 | X3: =F6 -> 320 | Y3: =L6 -> 0 | Z3: {=INDIRECT("D"&6+9*(ROW()-3))} -> 10292 | AA3: {=INDIRECT("C"&1+9*(ROW()-3))} -> 123
C4: 241.8 | D4: 309.2 | E4: 240.5 | F4: =MIN(C3:E5) -> 216.5 | L4: =MIN(I3:K5) -> 0 | O4: =IF(D4=0,"",IF(F5<Statistics!$G$3*(1-Statistics!$Q$1),FALSE,TRUE)) -> TRUE | P4: =IF(J4=0,"",IF(L5<Statistics!$G$3*(1-Statistics!$Q$1),FALSE,TRUE)) | Q4: Uniformity | R4: {=IF(MIN(IF(U3:U22>0,U3:U22,""))=0,S4,MIN(IF(U3:U22>0,U3:U22,"")))} -> 0.70019405 | S4: =IFERROR(AVERAGEIF(U3:U22,">0"),0) -> 0.70019405 | T4: =MAX(U3:U22) -> 0.70019405 | U4: =IF(F14=0,"",F14) | V4: =IF(F16=0,"",F16) | W4: =IF(F17=0,"",F17) | X4: =F15 -> 0 | Y4: =L15 -> 0 | Z4: {=INDIRECT("D"&6+9*(ROW()-3))} -> 0 | AA4: {=INDIRECT("C"&1+9*(ROW()-3))} -> 0
C5: 216.8 | D5: 265.6 | E5: 220.3 | F5: =IFERROR(F4/F3,"") -> 0.70019405 | L5: =IFERROR(L4/L3,"") | O5: =IF(C8<0.1,"",IF(F8<Statistics!$G$7*(1-2*Statistics!$Q$1),FALSE,TRUE)) -> TRUE | P5: =IF(I8<0.1,"",IF(L8<Statistics!$G$7*(1-2*Statistics!$Q$1),FALSE,TRUE)) | Q5: Contrast | R5: {=IF(MIN(IF(V3:V22>0,V3:V22,""))=0,S4,MIN(IF(V3:V22>0,V3:V22,"")))} -> 4433.874 | S5: =IFERROR(AVERAGEIF(V3:V22,">0"),0) -> 4433.874 | T5: =MAX(V3:V22) -> 4433.874 | U5: =IF(F23=0,"",F23) | V5: =IF(F25=0,"",F25) | W5: =IF(F26=0,"",F26) | X5: =F24 -> 0 | Y5: =L24 -> 0 | Z5: {=INDIRECT("D"&6+9*(ROW()-3))} -> 0 | AA5: {=INDIRECT("C"&1+9*(ROW()-3))} -> 0
C6: T | D6: 10292 | F6: =MAX(C3:E5,C7) -> 320 | I6: T | L6: =MAX(I3:K5,I7) -> 0 | Q6: Gamut | R6: {=IF(MIN(IF(W3:W22>0,W3:W22,""))=0,S4,MIN(IF(W3:W22>0,W3:W22,"")))} -> 0.71718505 | S6: =IFERROR(AVERAGEIF(W3:W22,">0"),0) -> 0.71718505 | T6: =MAX(W3:W22) -> 0.71718505 | U6: =IF(F32=0,"",F32) | V6: =IF(F34=0,"",F34) | W6: =IF(F35=0,"",F35) | X6: =F33 -> 0 | Y6: =L33 -> 0 | Z6: {=INDIRECT("D"&6+9*(ROW()-3))} -> 0 | AA6: {=INDIRECT("C"&1+9*(ROW()-3))} -> 0
B7: 工厂模式 | C7: 320 | D7: 0.07217165 | F7: =IFERROR(C7/D7,"") -> 4433.874 | H7: 工厂模式 | L7: =IFERROR(I7/J7,"") | Q7: Gamma | U7: =IF(F41=0,"",F41) | V7: =IF(F43=0,"",F43) | W7: =IF(F44=0,"",F44) | X7: =F42 -> 0 | Y7: =L42 -> 0 | Z7: {=INDIRECT("D"&6+9*(ROW()-3))} -> 0 | AA7: {=INDIRECT("C"&1+9*(ROW()-3))} -> 0
B8: 0.282 | C8: 0.636 | D8: 0.311 | E8: 0.156 | F8: =0.5*ABS(C8*D9-C9*D8+D8*E9-D9*E8+E8*C9-E9*C8)/F9 -> 0.71718505 | L8: =0.5*ABS(I8*J9-I9*J8+J8*K9-J9*K8+K8*I9-K9*I8)/L9 -> 0 | Q8: Temperature | R8: =MIN(D6,D15,D24,D33,D42,D51,D60,D69,D78,D87,J6,J15,J24,J33,J42,J51,J60,J69,J78,J87) -> 10292 | S8: =IFERROR(AVERAGE(D6,D15,D24,D33,D42,D51,D60,D69,D78,D87,J6,J15,J24,J33,J42,J51,J60,J69,J78,J87),0) -> 10292 | T8: =MAX(D6,D15,D24,D33,D42,D51,D60,D69,D78,D87,J6,J15,J24,J33,J42,J51,J60,J69,J78,J87) -> 10292 | U8: =IF(F50=0,"",F50) | V8: =IF(F52=0,"",F52) | W8: =IF(F53=0,"",F53) | X8: =F51 -> 0 | Y8: =L51 -> 0 | Z8: {=INDIRECT("D"&6+9*(ROW()-3))} -> 0 | AA8: {=INDIRECT("C"&1+9*(ROW()-3))} -> 0
B9: 0.293 | C9: 0.329 | D9: 0.615 | E9: 0.049 | F9: =0.5*ABS(0.674*0.712-0.218*0.326+0.218*0.08-0.14*0.712+0.14*0.326-0.674*0.08) -> 0.15915 | L9: =0.5*ABS(0.674*0.712-0.218*0.326+0.218*0.08-0.14*0.712+0.14*0.326-0.674*0.08) -> 0.15915 | Q9: White X | R9: =MIN(B8,B17,B26,B35,B44,B53,B62,B71,B80,B89,H8,H17,H26,H35,H44,H53,H62,H71,H80,H89) -> 0.282 | S9: =IFERROR(AVERAGE(B8,B17,B26,B35,B44,B53,B62,B71,B80,B89,H8,H17,H26,H35,H44,H53,H62,H71,H80,H89),0) -> 0.282 | T9: =MAX(B8,B17,B26,B35,B44,B53,B62,B71,B80,B89,H8,H17,H26,H35,H44,H53,H62,H71,H80,H89) -> 0.282 | U9: =IF(F59=0,"",F59) | V9: =IF(F61=0,"",F61) | W9: =IF(F62=0,"",F62) | X9: =F60 -> 0 | Y9: =L60 -> 0 | Z9: {=INDIRECT("D"&6+9*(ROW()-3))} -> 0 | AA9: {=INDIRECT("C"&1+9*(ROW()-3))} -> 0
A10: =A1+1 -> 2 | B10: SN | G10: =G1+1 -> 12 | H10: SN | Q10: White Y | R10: =MIN(B9,B18,B27,B36,B45,B54,B63,B72,B81,B90,H9,H18,H27,H36,H45,H54,H63,H72,H81,H90) -> 0.293 | S10: =IFERROR(AVERAGE(B9,B18,B27,B36,B45,B54,B63,B72,B81,B90,H9,H18,H27,H36,H45,H54,H63,H72,H81,H90),0) -> 0.293 | T10: =MAX(B9,B18,B27,B36,B45,B54,B63,B72,B81,B90,H9,H18,H27,H36,H45,H54,H63,H72,H81,H90) -> 0.293 | U10: =IF(F68=0,"",F68) | V10: =IF(F70=0,"",F70) | W10: =IF(F71=0,"",F71) | X10: =F69 -> 0 | Y10: =L69 -> 0 | Z10: {=INDIRECT("D"&6+9*(ROW()-3))} -> 0 | AA10: {=INDIRECT("C"&1+9*(ROW()-3))} -> 0
B11: HDMI | C11: =IF(Statistics!$R$2,Statistics!$Q$2,"Use '5/13 points' sheet !") -> UHD 9 @ 1/9 | H11: HDMI | I11: =IF(Statistics!$R$2,Statistics!$Q$2,"Use '5/13 points' sheet !") -> UHD 9 @ 1/9 | M11: =IF(Statistics!$R$2,CONCATENATE(IF(O11="","要测试九个点和白墙亮度; ",IF(O11,,"工厂模式白屏亮度不够, 再一次确认下; ")),IF(O12="","要测试白黑屏亮度; ",IF(O12,,"工厂模式黑屏亮度太大, 再一次确认下; ")),IF(O13="","要测试九个点亮度; ",IF(O13,,"9个白点之间的亮度差异太高, 再一次确认下; ")),IF(O14="","要测试四个颜色; ",IF(O14,,"3个红绿蓝颜色不太对的, 再一次确认下")),IF(F12>C16,"告诉Vova和工厂业务电视软件有大问题: 客人模式亮度不应该比工厂模式亮度还高","")),"不可以用这一页, 需要打开下一页‘5_13 points’!") -> 要测试九个点和白墙亮度; 要测试白黑屏亮度; 要测试九个点亮度; 要测试四个颜色; | N11: =IF(Statistics!$R$2,CONCATENATE(IF(P11="","要测试九个点和白墙亮度; ",IF(P11,,"工厂模式白屏亮度不够, 再一次确认下; ")),IF(P12="","要测试白黑屏亮度; ",IF(P12,,"工厂模式黑屏亮度太大, 再一次确认下; ")),IF(P13="","要测试九个点亮度; ",IF(P13,,"9个白点之间的亮度差异太高, 再一次确认下; ")),IF(P14="","要测试四个颜色; ",IF(P14,,"3个红绿蓝颜色不太对的, 再一次确认下")),IF(G12>D16,"告诉Vova和工厂业务电视软件有大问题: 客人模式亮度不应该比工厂模式亮度还高","")),"不可以用这一页, 需要打开下一页‘5_13 points’!") -> 要测试九个点和白墙亮度; 要测试白黑屏亮度; 要测试九个点亮度; 要测试四个颜色; | O11: =IF(C16<1,"",IF(F15<Statistics!$G$2*(1-Statistics!$Q$1),FALSE,TRUE)) | P11: =IF(I16<1,"",IF(L15<Statistics!$G$2*(1-Statistics!$Q$1),FALSE,TRUE)) | Q11: Red X | R11: =MIN(C8,C17,C26,C35,C44,C53,C62,C71,C80,C89,I8,I17,I26,I35,I44,I53,I62,I71,I80,I89) -> 0.636 | S11: =IFERROR(AVERAGE(C8,C17,C26,C35,C44,C53,C62,C71,C80,C89,I8,I17,I26,I35,I44,I53,I62,I71,I80,I89),0) -> 0.636 | T11: =MAX(C8,C17,C26,C35,C44,C53,C62,C71,C80,C89,I8,I17,I26,I35,I44,I53,I62,I71,I80,I89) -> 0.636 | U11: =IF(F77=0,"",F77) | V11: =IF(F79=0,"",F79) | W11: =IF(F80=0,"",F80) | X11: =F78 -> 0 | Y11: =L78 -> 0 | Z11: {=INDIRECT("D"&6+9*(ROW()-3))} -> 0 | AA11: {=INDIRECT("C"&1+9*(ROW()-3))} -> 0
F12: =MAX(C12:E14) -> 0 | L12: =MAX(I12:K14) -> 0 | O12: =IF(D16=0,"",IF(F16<Statistics!$G$5*(1-Statistics!$Q$1),FALSE,TRUE)) | P12: =IF(J16=0,"",IF(L16<Statistics!$G$5*(1-Statistics!$Q$1),FALSE,TRUE)) | Q12: Red Y | R12: =MIN(C9,C18,C27,C36,C45,C54,C63,C72,C81,C90,I9,I18,I27,I36,I45,I54,I63,I72,I81,I90) -> 0.329 | S12: =IFERROR(AVERAGE(C9,C18,C27,C36,C45,C54,C63,C72,C81,C90,I9,I18,I27,I36,I45,I54,I63,I72,I81,I90),0) -> 0.329 | T12: =MAX(C9,C18,C27,C36,C45,C54,C63,C72,C81,C90,I9,I18,I27,I36,I45,I54,I63,I72,I81,I90) -> 0.329 | U12: =IF(F86=0,"",F86) | V12: =IF(F88=0,"",F88) | W12: =IF(F89=0,"",F89) | X12: =F87 -> 0 | Y12: =L87 -> 0 | Z12: {=INDIRECT("D"&6+9*(ROW()-3))} -> 0 | AA12: {=INDIRECT("C"&1+9*(ROW()-3))} -> 0
F13: =MIN(C12:E14) -> 0 | L13: =MIN(I12:K14) -> 0 | O13: =IF(D13=0,"",IF(F14<Statistics!$G$3*(1-Statistics!$Q$1),FALSE,TRUE)) | P13: =IF(J13=0,"",IF(L14<Statistics!$G$3*(1-Statistics!$Q$1),FALSE,TRUE)) | Q13: Green X | R13: =MIN(D8,D17,D26,D35,D44,D53,D62,D71,D80,D89,J8,J17,J26,J35,J44,J53,J62,J71,J80,J89) -> 0.311 | S13: =IFERROR(AVERAGE(D8,D17,D26,D35,D44,D53,D62,D71,D80,D89,J8,J17,J26,J35,J44,J53,J62,J71,J80,J89),0) -> 0.311 | T13: =MAX(D8,D17,D26,D35,D44,D53,D62,D71,D80,D89,J8,J17,J26,J35,J44,J53,J62,J71,J80,J89) -> 0.311 | U13: =IF(L5=0,"",L5) | V13: =IF(L7=0,"",L7) | W13: =IF(L8=0,"",L8) | Z13: {=INDIRECT("J"&6+9*(ROW()-13))} -> 0 | AA13: {=INDIRECT("I"&1+9*(ROW()-13))} -> 0
F14: =IFERROR(F13/F12,"") | L14: =IFERROR(L13/L12,"") | O14: =IF(C17<0.1,"",IF(F17<Statistics!$G$7*(1-2*Statistics!$Q$1),FALSE,TRUE)) | P14: =IF(I17<0.1,"",IF(L17<Statistics!$G$7*(1-2*Statistics!$Q$1),FALSE,TRUE)) | Q14: Green Y | R14: =MIN(D9,D18,D27,D36,D45,D54,D63,D72,D81,D90,J9,J18,J27,J36,J45,J54,J63,J72,J81,J90) -> 0.615 | S14: =IFERROR(AVERAGE(D9,D18,D27,D36,D45,D54,D63,D72,D81,D90,J9,J18,J27,J36,J45,J54,J63,J72,J81,J90),0) -> 0.615 | T14: =MAX(D9,D18,D27,D36,D45,D54,D63,D72,D81,D90,J9,J18,J27,J36,J45,J54,J63,J72,J81,J90) -> 0.615 | U14: =IF(L14=0,"",L14) | V14: =IF(L16=0,"",L16) | W14: =IF(L17=0,"",L17) | Z14: {=INDIRECT("J"&6+9*(ROW()-13))} -> 0 | AA14: {=INDIRECT("I"&1+9*(ROW()-13))} -> 0
C15: T | F15: =MAX(C12:E14,C16) -> 0 | I15: T | L15: =MAX(I12:K14,I16) -> 0 | Q15: Blue X | R15: =MIN(E8,E17,E26,E35,E44,E53,E62,E71,E80,E89,K8,K17,K26,K35,K44,K53,K62,K71,K80,K89) -> 0.156 | S15: =IFERROR(AVERAGE(E8,E17,E26,E35,E44,E53,E62,E71,E80,E89,K8,K17,K26,K35,K44,K53,K62,K71,K80,K89),0) -> 0.156 | T15: =MAX(E8,E17,E26,E35,E44,E53,E62,E71,E80,E89,K8,K17,K26,K35,K44,K53,K62,K71,K80,K89) -> 0.156 | U15: =IF(L23=0,"",L23) | V15: =IF(L25=0,"",L25) | W15: =IF(L26=0,"",L26) | Z15: {=INDIRECT("J"&6+9*(ROW()-13))} -> 0 | AA15: {=INDIRECT("I"&1+9*(ROW()-13))} -> 0
B16: 工厂模式 | F16: =IFERROR(C16/D16,"") | H16: 工厂模式 | L16: =IFERROR(I16/J16,"") | Q16: Blue Y | R16: =MIN(E9,E18,E27,E36,E45,E54,E63,E72,E81,E90,K9,K18,K27,K36,K45,K54,K63,K72,K81,K90) -> 0.049 | S16: =IFERROR(AVERAGE(E9,E18,E27,E36,E45,E54,E63,E72,E81,E90,K9,K18,K27,K36,K45,K54,K63,K72,K81,K90),0) -> 0.049 | T16: =MAX(E9,E18,E27,E36,E45,E54,E63,E72,E81,E90,K9,K18,K27,K36,K45,K54,K63,K72,K81,K90) -> 0.049 | U16: =IF(L32=0,"",L32) | V16: =IF(L34=0,"",L34) | W16: =IF(L35=0,"",L35) | Z16: {=INDIRECT("J"&6+9*(ROW()-13))} -> 0 | AA16: {=INDIRECT("I"&1+9*(ROW()-13))} -> 0
F17: =0.5*ABS(C17*D18-C18*D17+D17*E18-D18*E17+E17*C18-E18*C17)/F18 -> 0 | L17: =0.5*ABS(I17*J18-I18*J17+J17*K18-J18*K17+K17*I18-K18*I17)/L18 -> 0 | U17: =IF(L41=0,"",L41) | V17: =IF(L43=0,"",L43) | W17: =IF(L44=0,"",L44) | Z17: {=INDIRECT("J"&6+9*(ROW()-13))} -> 0 | AA17: {=INDIRECT("I"&1+9*(ROW()-13))} -> 0
F18: =0.5*ABS(0.674*0.712-0.218*0.326+0.218*0.08-0.14*0.712+0.14*0.326-0.674*0.08) -> 0.15915 | L18: =0.5*ABS(0.674*0.712-0.218*0.326+0.218*0.08-0.14*0.712+0.14*0.326-0.674*0.08) -> 0.15915 | U18: =IF(L50=0,"",L50) | V18: =IF(L52=0,"",L52) | W18: =IF(L53=0,"",L53) | Z18: {=INDIRECT("J"&6+9*(ROW()-13))} -> 0 | AA18: {=INDIRECT("I"&1+9*(ROW()-13))} -> 0
A19: =A10+1 -> 3 | B19: SN | G19: =G10+1 -> 13 | H19: SN | U19: =IF(L59=0,"",L59) | V19: =IF(L61=0,"",L61) | W19: =IF(L62=0,"",L62) | Z19: {=INDIRECT("J"&6+9*(ROW()-13))} -> 0 | AA19: {=INDIRECT("I"&1+9*(ROW()-13))} -> 0
B20: HDMI | C20: =IF(Statistics!$R$2,Statistics!$Q$2,"Use '5/13 points' sheet !") -> UHD 9 @ 1/9 | H20: HDMI | I20: =IF(Statistics!$R$2,Statistics!$Q$2,"Use '5/13 points' sheet !") -> UHD 9 @ 1/9 | M20: =IF(Statistics!$R$2,CONCATENATE(IF(O20="","要测试九个点和白墙亮度; ",IF(O20,,"工厂模式白屏亮度不够, 再一次确认下; ")),IF(O21="","要测试白黑屏亮度; ",IF(O21,,"工厂模式黑屏亮度太大, 再一次确认下; ")),IF(O22="","要测试九个点亮度; ",IF(O22,,"9个白点之间的亮度差异太高, 再一次确认下; ")),IF(O23="","要测试四个颜色; ",IF(O23,,"3个红绿蓝颜色不太对的, 再一次确认下")),IF(F21>C25,"告诉Vova和工厂业务电视软件有大问题: 客人模式亮度不应该比工厂模式亮度还高","")),"不可以用这一页, 需要打开下一页‘5_13 points’!") -> 要测试九个点和白墙亮度; 要测试白黑屏亮度; 要测试九个点亮度; 要测试四个颜色; | N20: =IF(Statistics!$R$2,CONCATENATE(IF(P20="","要测试九个点和白墙亮度; ",IF(P20,,"工厂模式白屏亮度不够, 再一次确认下; ")),IF(P21="","要测试白黑屏亮度; ",IF(P21,,"工厂模式黑屏亮度太大, 再一次确认下; ")),IF(P22="","要测试九个点亮度; ",IF(P22,,"9个白点之间的亮度差异太高, 再一次确认下; ")),IF(P23="","要测试四个颜色; ",IF(P23,,"3个红绿蓝颜色不太对的, 再一次确认下")),IF(G21>D25,"告诉Vova和工厂业务电视软件有大问题: 客人模式亮度不应该比工厂模式亮度还高","")),"不可以用这一页, 需要打开下一页‘5_13 points’!") -> 要测试九个点和白墙亮度; 要测试白黑屏亮度; 要测试九个点亮度; 要测试四个颜色; | O20: =IF(C25<1,"",IF(F24<Statistics!$G$2*(1-Statistics!$Q$1),FALSE,TRUE)) | P20: =IF(I25<1,"",IF(L24<Statistics!$G$2*(1-Statistics!$Q$1),FALSE,TRUE)) | U20: =IF(L68=0,"",L68) | V20: =IF(L70=0,"",L70) | W20: =IF(L71=0,"",L71) | Z20: {=INDIRECT("J"&6+9*(ROW()-13))} -> 0 | AA20: {=INDIRECT("I"&1+9*(ROW()-13))} -> 0
F21: =MAX(C21:E23) -> 0 | L21: =MAX(I21:K23) -> 0 | O21: =IF(D25=0,"",IF(F25<Statistics!$G$5*(1-Statistics!$Q$1),FALSE,TRUE)) | P21: =IF(J25=0,"",IF(L25<Statistics!$G$5*(1-Statistics!$Q$1),FALSE,TRUE)) | U21: =IF(L77=0,"",L77) | V21: =IF(L79=0,"",L79) | W21: =IF(L80=0,"",L80) | Z21: {=INDIRECT("J"&6+9*(ROW()-13))} -> 0 | AA21: {=INDIRECT("I"&1+9*(ROW()-13))} -> 0
F22: =MIN(C21:E23) -> 0 | L22: =MIN(I21:K23) -> 0 | O22: =IF(D22=0,"",IF(F23<Statistics!$G$3*(1-Statistics!$Q$1),FALSE,TRUE)) | P22: =IF(J22=0,"",IF(L23<Statistics!$G$3*(1-Statistics!$Q$1),FALSE,TRUE)) | U22: =IF(L86=0,"",L86) | V22: =IF(L88=0,"",L88) | W22: =IF(L89=0,"",L89) | Z22: {=INDIRECT("J"&6+9*(ROW()-13))} -> 0 | AA22: {=INDIRECT("I"&1+9*(ROW()-13))} -> 0
F23: =IFERROR(F22/F21,"") | L23: =IFERROR(L22/L21,"") | O23: =IF(C26<0.1,"",IF(F26<Statistics!$G$7*(1-2*Statistics!$Q$1),FALSE,TRUE)) | P23: =IF(I26<0.1,"",IF(L26<Statistics!$G$7*(1-2*Statistics!$Q$1),FALSE,TRUE)) | Z23: =IFERROR(AVERAGEIF(Z3:Z22,">0"),0) -> 10292
C24: T | F24: =MAX(C21:E23,C25) -> 0 | I24: T | L24: =MAX(I21:K23,I25) -> 0 | Z24: {=INDEX(Z3:Z22,MATCH(MIN(ABS(Z3:Z22-Z23)),ABS(Z3:Z22-Z23),0))} -> 10292 | AA24: =VLOOKUP(Z24,Z3:AA22,2,0) -> 123
B25: 工厂模式 | F25: =IFERROR(C25/D25,"") | H25: 工厂模式 | L25: =IFERROR(I25/J25,"")
F26: =0.5*ABS(C26*D27-C27*D26+D26*E27-D27*E26+E26*C27-E27*C26)/F27 -> 0 | L26: =0.5*ABS(I26*J27-I27*J26+J26*K27-J27*K26+K26*I27-K27*I26)/L27 -> 0
F27: =0.5*ABS(0.674*0.712-0.218*0.326+0.218*0.08-0.14*0.712+0.14*0.326-0.674*0.08) -> 0.15915 | L27: =0.5*ABS(0.674*0.712-0.218*0.326+0.218*0.08-0.14*0.712+0.14*0.326-0.674*0.08) -> 0.15915
A28: =A19+1 -> 4 | B28: SN | G28: =G19+1 -> 14 | H28: SN
B29: HDMI | C29: =IF(Statistics!$R$2,Statistics!$Q$2,"Use '5/13 points' sheet !") -> UHD 9 @ 1/9 | H29: HDMI | I29: =IF(Statistics!$R$2,Statistics!$Q$2,"Use '5/13 points' sheet !") -> UHD 9 @ 1/9 | M29: =IF(Statistics!$R$2,CONCATENATE(IF(O29="","要测试九个点和白墙亮度; ",IF(O29,,"工厂模式白屏亮度不够, 再一次确认下; ")),IF(O30="","要测试白黑屏亮度; ",IF(O30,,"工厂模式黑屏亮度太大, 再一次确认下; ")),IF(O31="","要测试九个点亮度; ",IF(O31,,"9个白点之间的亮度差异太高, 再一次确认下; ")),IF(O32="","要测试四个颜色; ",IF(O32,,"3个红绿蓝颜色不太对的, 再一次确认下")),IF(F30>C34,"告诉Vova和工厂业务电视软件有大问题: 客人模式亮度不应该比工厂模式亮度还高","")),"不可以用这一页, 需要打开下一页‘5_13 points’!") -> 要测试九个点和白墙亮度; 要测试白黑屏亮度; 要测试九个点亮度; 要测试四个颜色; | N29: =IF(Statistics!$R$2,CONCATENATE(IF(P29="","要测试九个点和白墙亮度; ",IF(P29,,"工厂模式白屏亮度不够, 再一次确认下; ")),IF(P30="","要测试白黑屏亮度; ",IF(P30,,"工厂模式黑屏亮度太大, 再一次确认下; ")),IF(P31="","要测试九个点亮度; ",IF(P31,,"9个白点之间的亮度差异太高, 再一次确认下; ")),IF(P32="","要测试四个颜色; ",IF(P32,,"3个红绿蓝颜色不太对的, 再一次确认下")),IF(G30>D34,"告诉Vova和工厂业务电视软件有大问题: 客人模式亮度不应该比工厂模式亮度还高","")),"不可以用这一页, 需要打开下一页‘5_13 points’!") -> 要测试九个点和白墙亮度; 要测试白黑屏亮度; 要测试九个点亮度; 要测试四个颜色; | O29: =IF(C34<1,"",IF(F33<Statistics!$G$2*(1-Statistics!$Q$1),FALSE,TRUE)) | P29: =IF(I34<1,"",IF(L33<Statistics!$G$2*(1-Statistics!$Q$1),FALSE,TRUE))
F30: =MAX(C30:E32) -> 0 | L30: =MAX(I30:K32) -> 0 | O30: =IF(D34=0,"",IF(F34<Statistics!$G$5*(1-Statistics!$Q$1),FALSE,TRUE)) | P30: =IF(J34=0,"",IF(L34<Statistics!$G$5*(1-Statistics!$Q$1),FALSE,TRUE))
F31: =MIN(C30:E32) -> 0 | L31: =MIN(I30:K32) -> 0 | O31: =IF(D31=0,"",IF(F32<Statistics!$G$3*(1-Statistics!$Q$1),FALSE,TRUE)) | P31: =IF(J31=0,"",IF(L32<Statistics!$G$3*(1-Statistics!$Q$1),FALSE,TRUE))
F32: =IFERROR(F31/F30,"") | L32: =IFERROR(L31/L30,"") | O32: =IF(C35<0.1,"",IF(F35<Statistics!$G$7*(1-2*Statistics!$Q$1),FALSE,TRUE)) | P32: =IF(I35<0.1,"",IF(L35<Statistics!$G$7*(1-2*Statistics!$Q$1),FALSE,TRUE))
C33: T | F33: =MAX(C30:E32,C34) -> 0 | I33: T | L33: =MAX(I30:K32,I34) -> 0
B34: 工厂模式 | F34: =IFERROR(C34/D34,"") | H34: 工厂模式 | L34: =IFERROR(I34/J34,"")
F35: =0.5*ABS(C35*D36-C36*D35+D35*E36-D36*E35+E35*C36-E36*C35)/F36 -> 0 | L35: =0.5*ABS(I35*J36-I36*J35+J35*K36-J36*K35+K35*I36-K36*I35)/L36 -> 0
F36: =0.5*ABS(0.674*0.712-0.218*0.326+0.218*0.08-0.14*0.712+0.14*0.326-0.674*0.08) -> 0.15915 | L36: =0.5*ABS(0.674*0.712-0.218*0.326+0.218*0.08-0.14*0.712+0.14*0.326-0.674*0.08) -> 0.15915
A37: =A28+1 -> 5 | B37: SN | G37: =G28+1 -> 15 | H37: SN
B38: HDMI | C38: =IF(Statistics!$R$2,Statistics!$Q$2,"Use '5/13 points' sheet !") -> UHD 9 @ 1/9 | H38: HDMI | I38: =IF(Statistics!$R$2,Statistics!$Q$2,"Use '5/13 points' sheet !") -> UHD 9 @ 1/9 | M38: =IF(Statistics!$R$2,CONCATENATE(IF(O38="","要测试九个点和白墙亮度; ",IF(O38,,"工厂模式白屏亮度不够, 再一次确认下; ")),IF(O39="","要测试白黑屏亮度; ",IF(O39,,"工厂模式黑屏亮度太大, 再一次确认下; ")),IF(O40="","要测试九个点亮度; ",IF(O40,,"9个白点之间的亮度差异太高, 再一次确认下; ")),IF(O41="","要测试四个颜色; ",IF(O41,,"3个红绿蓝颜色不太对的, 再一次确认下")),IF(F39>C43,"告诉Vova和工厂业务电视软件有大问题: 客人模式亮度不应该比工厂模式亮度还高","")),"不可以用这一页, 需要打开下一页‘5_13 points’!") -> 要测试九个点和白墙亮度; 要测试白黑屏亮度; 要测试九个点亮度; 要测试四个颜色; | N38: =IF(Statistics!$R$2,CONCATENATE(IF(P38="","要测试九个点和白墙亮度; ",IF(P38,,"工厂模式白屏亮度不够, 再一次确认下; ")),IF(P39="","要测试白黑屏亮度; ",IF(P39,,"工厂模式黑屏亮度太大, 再一次确认下; ")),IF(P40="","要测试九个点亮度; ",IF(P40,,"9个白点之间的亮度差异太高, 再一次确认下; ")),IF(P41="","要测试四个颜色; ",IF(P41,,"3个红绿蓝颜色不太对的, 再一次确认下")),IF(G39>D43,"告诉Vova和工厂业务电视软件有大问题: 客人模式亮度不应该比工厂模式亮度还高","")),"不可以用这一页, 需要打开下一页‘5_13 points’!") -> 要测试九个点和白墙亮度; 要测试白黑屏亮度; 要测试九个点亮度; 要测试四个颜色; | O38: =IF(C43<1,"",IF(F42<Statistics!$G$2*(1-Statistics!$Q$1),FALSE,TRUE)) | P38: =IF(I43<1,"",IF(L42<Statistics!$G$2*(1-Statistics!$Q$1),FALSE,TRUE))
F39: =MAX(C39:E41) -> 0 | L39: =MAX(I39:K41) -> 0 | O39: =IF(D43=0,"",IF(F43<Statistics!$G$5*(1-Statistics!$Q$1),FALSE,TRUE)) | P39: =IF(J43=0,"",IF(L43<Statistics!$G$5*(1-Statistics!$Q$1),FALSE,TRUE))
F40: =MIN(C39:E41) -> 0 | L40: =MIN(I39:K41) -> 0 | O40: =IF(D40=0,"",IF(F41<Statistics!$G$3*(1-Statistics!$Q$1),FALSE,TRUE)) | P40: =IF(J40=0,"",IF(L41<Statistics!$G$3*(1-Statistics!$Q$1),FALSE,TRUE))
...

Sheet 5_13 points
A1: 1 | B1: SN | I1: 11 | J1: SN
B2: HDMI | D2: =IF(Statistics!$R$2,"Use '9 points' sheet !",Statistics!$Q$2) -> Use '9 points' sheet ! | J2: HDMI | L2: =IF(Statistics!$R$2,"Use '9 points' sheet !",Statistics!$Q$2) -> Use '9 points' sheet ! | Q2: =IF(Statistics!$R$2,"不可以用这一页, 需要打开下一页‘9 points’!",CONCATENATE(IF(S2="","要测试九个点和白墙亮度; ",IF(S2,,"工厂模式白屏亮度不够, 再一次确认下; ")),IF(S3="","要测试白黑屏亮度; ",IF(S3,,"工厂模式黑屏亮度太大, 再一次确认下; ")),IF(S5="","要测试九个点亮度; ",IF(S5,,"9个白点之间的亮度差异太高, 再一次确认下; ")),IF(S7="","要测试四个颜色; ",IF(S7,,"3个红绿蓝颜色不太对的, 再一次确认下")),IF(H3>D9,"告诉Vova和工厂业务电视软件有大问题: 客人模式亮度不应该比工厂模式亮度还高",""))) -> 不可以用这一页, 需要打开下一页‘9 points’! | R2: =IF(Statistics!$R$2,"不可以用这一页, 需要打开下一页‘9 points’!",CONCATENATE(IF(T2="","要测试九个点和白墙亮度; ",IF(T2,,"工厂模式白屏亮度不够, 再一次确认下; ")),IF(T3="","要测试白黑屏亮度; ",IF(T3,,"工厂模式黑屏亮度太大, 再一次确认下; ")),IF(T5="","要测试九个点亮度; ",IF(T5,,"9个白点之间的亮度差异太高, 再一次确认下; ")),IF(T7="","要测试四个颜色; ",IF(T7,,"3个红绿蓝颜色不太对的, 再一次确认下")),IF(P3>L9,"告诉Vova和工厂业务电视软件有大问题: 客人模式亮度不应该比工厂模式亮度还高",""))) -> 不可以用这一页, 需要打开下一页‘9 points’! | S2: =IF(D9<1,"",IF(H8<Statistics!$G$2*(1-Statistics!$Q$1),FALSE,TRUE)) | T2: =IF(L9<1,"",IF(P8<Statistics!$G$2*(1-Statistics!$Q$1),FALSE,TRUE)) | V2: MIN | W2: TYP | X2: MAX | Y2: UF 1/10 | Z2: UF 1/4 | AA2: CR | AB2: CG | AE2: CT | AF2: SN
H3: =MAX(C3:G7) -> 0 | P3: =MAX(K3:O7) -> 0 | S3: =IF(F9=0,"",IF(H9<Statistics!$G$5*(1-Statistics!$Q$1),FALSE,TRUE)) | T3: =IF(N9=0,"",IF(P9<Statistics!$G$5*(1-Statistics!$Q$1),FALSE,TRUE)) | U3: Brightness | V3: {=MIN(IF(AC3:AD12>0,AC3:AD12,""))} -> 0 | W3: =IFERROR(AVERAGEIF(AC3:AD12,">0"),0) -> 0 | X3: =MAX(AC3:AD12) -> 0 | Y3: =IF(H6=0,"",H6) | Z3: =IF(H7=0,"",H7) | AA3: =IF(H9=0,"",H9) | AB3: =IF(H10=0,"",H10) | AC3: =H8 -> 0 | AD3: =P8 -> 0 | AE3: {=INDIRECT("D"&8+11*(ROW()-3))} -> 0 | AF3: {=INDIRECT("C"&1+11*(ROW()-3))} -> 0
H4: =MAX(D4:F6) -> 0 | P4: =MAX(L4:N6) -> 0 | S4: =IF(E5=0,"",IF(H6<Statistics!$G$3*(1-Statistics!$Q$1),FALSE,TRUE)) | T4: =IF(M5=0,"",IF(P6<Statistics!$G$3*(1-Statistics!$Q$1),FALSE,TRUE)) | U4: Uniformity 1/10 | V4: {=MIN(IF(Y3:Y22>0,Y3:Y22,""))} -> 0 | W4: =IFERROR(AVERAGEIF(Y3:Y22,">0"),0) -> 0 | X4: =MAX(Y3:Y22) -> 0 | Y4: =IF(H17=0,"",H17) | Z4: =IF(H18=0,"",H18) | AA4: =IF(H20=0,"",H20) | AB4: =IF(H21=0,"",H21) | AC4: =H19 -> 0 | AD4: =P19 -> 0 | AE4: {=INDIRECT("D"&8+11*(ROW()-3))} -> 0 | AF4: {=INDIRECT("C"&1+11*(ROW()-3))} -> 0
S5: =IF(E5=0,"",IF(H7<Statistics!$G$4*(1-Statistics!$Q$1),FALSE,TRUE)) | T5: =IF(M5=0,"",IF(P7<Statistics!$G$4*(1-Statistics!$Q$1),FALSE,TRUE)) | U5: Uniformity 1/4 | V5: {=MIN(IF(Z3:Z22>0,Z3:Z22,""))} -> 0 | W5: =IFERROR(AVERAGEIF(Z3:Z22,">0"),0) -> 0 | X5: =MAX(Z3:Z22) -> 0 | Y5: =IF(H28=0,"",H28) | Z5: =IF(H29=0,"",H29) | AA5: =IF(H31=0,"",H31) | AB5: =IF(H32=0,"",H32) | AC5: =H30 -> 0 | AD5: =P30 -> 0 | AE5: {=INDIRECT("D"&8+11*(ROW()-3))} -> 0 | AF5: {=INDIRECT("C"&1+11*(ROW()-3))} -> 0
H6: =IFERROR(MIN(C3:G7)/MAX(C3:G7),"") | P6: =IFERROR(MIN(K3:O7)/MAX(K3:O7),"") | U6: Contrast | V6: =MIN(AA3:AA22) -> 0 | W6: =IFERROR(AVERAGEIF(AA3:AA22,">0"),0) -> 0 | X6: =MAX(AA3:AA22) -> 0 | Y6: =IF(H39=0,"",H39) | Z6: =IF(H40=0,"",H40) | AA6: =IF(H42=0,"",H42) | AB6: =IF(H43=0,"",H43) | AC6: =H41 -> 0 | AD6: =P41 -> 0 | AE6: {=INDIRECT("D"&8+11*(ROW()-3))} -> 0 | AF6: {=INDIRECT("C"&1+11*(ROW()-3))} -> 0
H7: =IFERROR(MIN(D4:F6)/MAX(D4:F6),"") | P7: =IFERROR(MIN(L4:N6)/MAX(L4:N6),"") | S7: =IF(E10<0.1,"",IF(H10<Statistics!$G$7*(1-2*Statistics!$Q$1),FALSE,TRUE)) | T7: =IF(M10<0.1,"",IF(P10<Statistics!$G$7*(1-2*Statistics!$Q$1),FALSE,TRUE)) | U7: Gamut | V7: =MIN(AB3:AB22) -> 0 | W7: =IFERROR(AVERAGEIF(AB3:AB22,">0"),0) -> 0 | X7: =MAX(AB3:AB22) -> 0 | Y7: =IF(H50=0,"",H50) | Z7: =IF(H51=0,"",H51) | AA7: =IF(H53=0,"",H53) | AB7: =IF(H54=0,"",H54) | AC7: =H52 -> 0 | AD7: =P52 -> 0 | AE7: {=INDIRECT("D"&8+11*(ROW()-3))} -> 0 | AF7: {=INDIRECT("C"&1+11*(ROW()-3))} -> 0
C8: T | H8: =MAX(C3:G7,D9) -> 0 | K8: T | P8: =MAX(K3:O7,L9) -> 0 | U8: Gamma | Y8: =IF(H61=0,"",H61) | Z8: =IF(H62=0,"",H62) | AA8: =IF(H64=0,"",H64) | AB8: =IF(H65=0,"",H65) | AC8: =H63 -> 0 | AD8: =P63 -> 0 | AE8: {=INDIRECT("D"&8+11*(ROW()-3))} -> 0 | AF8: {=INDIRECT("C"&1+11*(ROW()-3))} -> 0
B9: 工厂模式白黑墙 | H9: =IFERROR(D9/F9,"") | J9: 工厂模式白黑墙 | P9: =IFERROR(L9/N9,"") | U9: Temperature | V9: =MIN(E8,E19,E30,E41,E52,E63,E74,E85,E96,E107,M8,M19,M30,M41,M52,M63,M74,M85,M96,M107) -> 0 | W9: =IFERROR(AVERAGE(E8,E19,E30,E41,E52,E63,E74,E85,E96,E107,M8,M19,M30,M41,M52,M63,M74,M85,M96,M107),0) -> 0 | X9: =MAX(E8,E19,E30,E41,E52,E63,E74,E85,E96,E107,M8,M19,M30,M41,M52,M63,M74,M85,M96,M107) -> 0 | Y9: =IF(H72=0,"",H72) | Z9: =IF(H73=0,"",H73) | AA9: =IF(H75=0,"",H75) | AB9: =IF(H76=0,"",H76) | AC9: =H74 -> 0 | AD9: =P74 -> 0 | AE9: {=INDIRECT("D"&8+11*(ROW()-3))} -> 0 | AF9: {=INDIRECT("C"&1+11*(ROW()-3))} -> 0
B10: WRGB X-Y coorditane | H10: =0.5*ABS(E10*F11-E11*F10+F10*G11-F11*G10+G10*E11-G11*E10)/H11 -> 0 | J10: WRGB X-Y coorditane | P10: =0.5*ABS(M10*N11-M11*N10+N10*O11-N11*O10+O10*M11-O11*M10)/P11 -> 0 | U10: White X | V10: =MIN(D10,D21,D32,D43,D54,D65,D76,D87,D98,D109,L10,L21,L32,L43,L54,L65,L76,L87,L98,L109) -> 0 | W10: =IFERROR(AVERAGE(D10,D21,D32,D43,D54,D65,D76,D87,D98,D109,L10,L21,L32,L43,L54,L65,L76,L87,L98,L109),0) -> 0 | X10: =MAX(D10,D21,D32,D43,D54,D65,D76,D87,D98,D109,L10,L21,L32,L43,L54,L65,L76,L87,L98,L109) -> 0 | Y10: =IF(H83=0,"",H83) | Z10: =IF(H84=0,"",H84) | AA10: =IF(H86=0,"",H86) | AB10: =IF(H87=0,"",H87) | AC10: =H85 -> 0 | AD10: =P85 -> 0 | AE10: {=INDIRECT("D"&8+11*(ROW()-3))} -> 0 | AF10: {=INDIRECT("C"&1+11*(ROW()-3))} -> 0
H11: =0.5*ABS(0.674*0.712-0.218*0.326+0.218*0.08-0.14*0.712+0.14*0.326-0.674*0.08) -> 0.15915 | P11: =0.5*ABS(0.674*0.712-0.218*0.326+0.218*0.08-0.14*0.712+0.14*0.326-0.674*0.08) -> 0.15915 | U11: White Y | V11: =MIN(D11,D22,D33,D44,D55,D66,D77,D88,D99,D110,L11,L22,L33,L44,L55,L66,L77,L88,L99,L110) -> 0 | W11: =IFERROR(AVERAGE(D11,D22,D33,D44,D55,D66,D77,D88,D99,D110,L11,L22,L33,L44,L55,L66,L77,L88,L99,L110),0) -> 0 | X11: =MAX(D11,D22,D33,D44,D55,D66,D77,D88,D99,D110,L11,L22,L33,L44,L55,L66,L77,L88,L99,L110) -> 0 | Y11: =IF(H94=0,"",H94) | Z11: =IF(H95=0,"",H95) | AA11: =IF(H97=0,"",H97) | AB11: =IF(H98=0,"",H98) | AC11: =H96 -> 0 | AD11: =P96 -> 0 | AE11: {=INDIRECT("D"&8+11*(ROW()-3))} -> 0 | AF11: {=INDIRECT("C"&1+11*(ROW()-3))} -> 0
A12: =A1+1 -> 2 | B12: SN | I12: =I1+1 -> 12 | J12: SN | U12: Red X | V12: =MIN(E10,E21,E32,E43,E54,E65,E76,E87,E98,E109,M10,M21,M32,M43,M54,M65,M76,M87,M98,M109) -> 0 | W12: =IFERROR(AVERAGE(E10,E21,E32,E43,E54,E65,E76,E87,E98,E109,M10,M21,M32,M43,M54,M65,M76,M87,M98,M109),0) -> 0 | X12: =MAX(E10,E21,E32,E43,E54,E65,E76,E87,E98,E109,M10,M21,M32,M43,M54,M65,M76,M87,M98,M109) -> 0 | Y12: =IF(H105=0,"",H105) | Z12: =IF(H106=0,"",H106) | AA12: =IF(H108=0,"",H108) | AB12: =IF(H109=0,"",H109) | AC12: =H107 -> 0 | AD12: =P107 -> 0 | AE12: {=INDIRECT("D"&8+11*(ROW()-3))} -> 0 | AF12: {=INDIRECT("C"&1+11*(ROW()-3))} -> 0
B13: HDMI | D13: =IF(Statistics!$R$2,"Use '9 points' sheet !",Statistics!$Q$2) -> Use '9 points' sheet ! | J13: HDMI | L13: =IF(Statistics!$R$2,"Use '9 points' sheet !",Statistics!$Q$2) -> Use '9 points' sheet ! | Q13: =IF(Statistics!$R$2,"不可以用这一页, 需要打开下一页‘9 points’!",CONCATENATE(IF(S13="","要测试九个点和白墙亮度; ",IF(S13,,"工厂模式白屏亮度不够, 再一次确认下; ")),IF(S14="","要测试白黑屏亮度; ",IF(S14,,"工厂模式黑屏亮度太大, 再一次确认下; ")),IF(S16="","要测试九个点亮度; ",IF(S16,,"9个白点之间的亮度差异太高, 再一次确认下; ")),IF(S18="","要测试四个颜色; ",IF(S18,,"3个红绿蓝颜色不太对的, 再一次确认下")),IF(H14>D20,"告诉Vova和工厂业务电视软件有大问题: 客人模式亮度不应该比工厂模式亮度还高",""))) -> 不可以用这一页, 需要打开下一页‘9 points’! | R13: =IF(Statistics!$R$2,"不可以用这一页, 需要打开下一页‘9 points’!",CONCATENATE(IF(T13="","要测试九个点和白墙亮度; ",IF(T13,,"工厂模式白屏亮度不够, 再一次确认下; ")),IF(T14="","要测试白黑屏亮度; ",IF(T14,,"工厂模式黑屏亮度太大, 再一次确认下; ")),IF(T16="","要测试九个点亮度; ",IF(T16,,"9个白点之间的亮度差异太高, 再一次确认下; ")),IF(T18="","要测试四个颜色; ",IF(T18,,"3个红绿蓝颜色不太对的, 再一次确认下")),IF(P14>L20,"告诉Vova和工厂业务电视软件有大问题: 客人模式亮度不应该比工厂模式亮度还高",""))) -> 不可以用这一页, 需要打开下一页‘9 points’! | S13: =IF(D20<1,"",IF(H19<Statistics!$G$2*(1-Statistics!$Q$1),FALSE,TRUE)) | T13: =IF(L20<1,"",IF(P19<Statistics!$G$2*(1-Statistics!$Q$1),FALSE,TRUE)) | U13: Red Y | V13: =MIN(E11,E22,E33,E44,E55,E66,E77,E88,E99,E110,M11,M22,M33,M44,M55,M66,M77,M88,M99,M110) -> 0 | W13: =IFERROR(AVERAGE(E11,E22,E33,E44,E55,E66,E77,E88,E99,E110,M11,M22,M33,M44,M55,M66,M77,M88,M99,M110),0) -> 0 | X13: =MAX(E11,E22,E33,E44,E55,E66,E77,E88,E99,E110,M11,M22,M33,M44,M55,M66,M77,M88,M99,M110) -> 0 | Y13: =IF(P6=0,"",P6) | Z13: =IF(P7=0,"",P7) | AA13: =IF(P9=0,"",P9) | AB13: =IF(P10=0,"",P10) | AE13: {=INDIRECT("L"&8+11*(ROW()-13))} -> 0 | AF13: {=INDIRECT("K"&1+11*(ROW()-13))} -> 0
H14: =MAX(C14:G18) -> 0 | P14: =MAX(K14:O18) -> 0 | S14: =IF(F20=0,"",IF(H20<Statistics!$G$5*(1-Statistics!$Q$1),FALSE,TRUE)) | T14: =IF(N20=0,"",IF(P20<Statistics!$G$5*(1-Statistics!$Q$1),FALSE,TRUE)) | U14: Green X | V14: =MIN(F10,F21,F32,F43,F54,F65,F76,F87,F98,F109,N10,N21,N32,N43,N54,N65,N76,N87,N98,N109) -> 0 | W14: =IFERROR(AVERAGE(F10,F21,F32,F43,F54,F65,F76,F87,F98,F109,N10,N21,N32,N43,N54,N65,N76,N87,N98,N109),0) -> 0 | X14: =MAX(F10,F21,F32,F43,F54,F65,F76,F87,F98,F109,N10,N21,N32,N43,N54,N65,N76,N87,N98,N109) -> 0 | Y14: =IF(P17=0,"",P17) | Z14: =IF(P18=0,"",P18) | AA14: =IF(P20=0,"",P20) | AB14: =IF(P21=0,"",P21) | AE14: {=INDIRECT("L"&8+11*(ROW()-13))} -> 0 | AF14: {=INDIRECT("K"&1+11*(ROW()-13))} -> 0
H15: =MAX(D15:F17) -> 0 | P15: =MAX(L15:N17) -> 0 | S15: =IF(E16=0,"",IF(H17<Statistics!$G$3*(1-Statistics!$Q$1),FALSE,TRUE)) | T15: =IF(M16=0,"",IF(P17<Statistics!$G$3*(1-Statistics!$Q$1),FALSE,TRUE)) | U15: Green Y | V15: =MIN(F11,F22,F33,F44,F55,F66,F77,F88,F99,F110,N11,N22,N33,N44,N55,N66,N77,N88,N99,N110) -> 0 | W15: =IFERROR(AVERAGE(F11,F22,F33,F44,F55,F66,F77,F88,F99,F110,N11,N22,N33,N44,N55,N66,N77,N88,N99,N110),0) -> 0 | X15: =MAX(F11,F22,F33,F44,F55,F66,F77,F88,F99,F110,N11,N22,N33,N44,N55,N66,N77,N88,N99,N110) -> 0 | Y15: =IF(P28=0,"",P28) | Z15: =IF(P29=0,"",P29) | AA15: =IF(P31=0,"",P31) | AB15: =IF(P32=0,"",P32) | AE15: {=INDIRECT("L"&8+11*(ROW()-13))} -> 0 | AF15: {=INDIRECT("K"&1+11*(ROW()-13))} -> 0
S16: =IF(E16=0,"",IF(H18<Statistics!$G$4*(1-Statistics!$Q$1),FALSE,TRUE)) | T16: =IF(M16=0,"",IF(P18<Statistics!$G$4*(1-Statistics!$Q$1),FALSE,TRUE)) | U16: Blue X | V16: =MIN(G10,G21,G32,G43,G54,G65,G76,G87,G98,G109,O10,O21,O32,O43,O54,O65,O76,O87,O98,O109) -> 0 | W16: =IFERROR(AVERAGE(G10,G21,G32,G43,G54,G65,G76,G87,G98,G109,O10,O21,O32,O43,O54,O65,O76,O87,O98,O109),0) -> 0 | X16: =MAX(G10,G21,G32,G43,G54,G65,G76,G87,G98,G109,O10,O21,O32,O43,O54,O65,O76,O87,O98,O109) -> 0 | Y16: =IF(P39=0,"",P39) | Z16: =IF(P40=0,"",P40) | AA16: =IF(P42=0,"",P42) | AB16: =IF(P43=0,"",P43) | AE16: {=INDIRECT("L"&8+11*(ROW()-13))} -> 0 | AF16: {=INDIRECT("K"&1+11*(ROW()-13))} -> 0
H17: =IFERROR(MIN(C14:G18)/MAX(C14:G18),"") | P17: =IFERROR(MIN(K14:O18)/MAX(K14:O18),"") | U17: Blue Y | V17: =MIN(G11,G22,G33,G44,G55,G66,G77,G88,G99,G110,O11,O22,O33,O44,O55,O66,O77,O88,O99,O110) -> 0 | W17: =IFERROR(AVERAGE(G11,G22,G33,G44,G55,G66,G77,G88,G99,G110,O11,O22,O33,O44,O55,O66,O77,O88,O99,O110),0) -> 0 | X17: =MAX(G11,G22,G33,G44,G55,G66,G77,G88,G99,G110,O11,O22,O33,O44,O55,O66,O77,O88,O99,O110) -> 0 | Y17: =IF(P50=0,"",P50) | Z17: =IF(P51=0,"",P51) | AA17: =IF(P53=0,"",P53) | AB17: =IF(P54=0,"",P54) | AE17: {=INDIRECT("L"&8+11*(ROW()-13))} -> 0 | AF17: {=INDIRECT("K"&1+11*(ROW()-13))} -> 0
